Workbook

Sheet distribuiçao nas atividades
A1: > | B1: svytable(~idade_categ+sub_grupo_cnae, | C1: design | D1: = | E1: mulheres_func_pub_aux) | I1: > | J1: svytable(~idade_categ+sub_grupo_cnae, | K1: design | L1: = | M1: mulheres_func_pub_aux)
B2: sub_grupo_cnae | J2: sub_grupo_cnae
B3: idade_categ | C3: adm_e_gestao_publica | D3: educacao | E3: outras | F3: saude | G3: tecnologia | J3: idade_categ | K3: adm_e_gestao_publica | L3: educacao | M3: outras | N3: saude | O3: tecnologia
B4: 15-19 | C4: 15503.606 | D4: 17333.867 | E4: 10036.252 | F4: 3025.8801 | G4: 63.10832 | J4: 15-19 | K4: 6530.2336 | L4: 4072.5238 | M4: 504.07 | N4: 1254.2995 | O4: 368.9536
B5: 20-24 | C5: 49903.187 | D5: 91467.208 | E5: 15488.244 | F5: 11902.723 | G5: 164.36114 | J5: 20-24 | K5: 52835.538 | L5: 43930.978 | M5: 3305.8311 | N5: 18172.722 | O5: 2321.7293
B6: 25-29 | C6: 72723.555 | D6: 133881.38 | E6: 14816.034 | F6: 20198.175 | G6: 105.29502 | J6: 25-29 | K6: 109576.08 | L6: 109988.29 | M6: 6407.4717 | N6: 43504.488 | O6: 5074.0006
B7: 30-34 | C7: 92983.7 | D7: 168356.79 | E7: 17304.859 | F7: 28478.075 | G7: 131.43081 | J7: 30-34 | K7: 132276.64 | L7: 163435.79 | M7: 6784.2355 | N7: 50935.161 | O7: 4796.8627
B8: 35-39 | C8: 108539.86 | D8: 181423.15 | E8: 19140.835 | F8: 33229.751 | G8: 97.47529 | J8: 35-39 | K8: 132336.94 | L8: 179842.01 | M8: 6310.6152 | N8: 47852.557 | O8: 4701.6727
B9: 40-44 | C9: 97889.13 | D9: 164823.15 | E9: 17901.71 | F9: 33209.345 | G9: 103.65801 | J9: 40-44 | K9: 142696.5 | L9: 197418.91 | M9: 6955.4843 | N9: 48388.262 | O9: 4660.0029
B10: 45-49 | C10: 71493.046 | D10: 138796.67 | E10: 14051.341 | F10: 25082.275 | G10: 48.79853 | J10: 45-49 | K10: 146847.8 | L10: 197686.11 | M10: 7863.0523 | N10: 48061.835 | O10: 4736.5768
B11: Total | C11: =SUM(C4:C10) -> 509036.09 | D11: =SUM(D4:D10) -> 896082.21 | E11: =SUM(E4:E10) -> 108739.28 | F11: =SUM(F4:F10) -> 155126.22 | G11: =SUM(G4:G10) -> 714.12712 | J11: Total | K11: =SUM(K4:K10) -> 723099.73 | L11: =SUM(L4:L10) -> 896374.61 | M11: =SUM(M4:M10) -> 38130.76 | N11: =SUM(N4:N10) -> 258169.33 | O11: =SUM(O4:O10) -> 26659.799
B13: idade_categ | C13: adm_e_gestao_publica | D13: educacao | E13: outras | F13: saude | G13: tecnologia | J13: idade_categ | K13: adm_e_gestao_publica | L13: educacao | M13: outras | N13: saude | O13: tecnologia
B14: 15-19 | C14: =C4/C$11 -> 0.030456792 | D14: =D4/D$11 -> 0.019344059 | E14: =E4/E$11 -> 0.092296481 | F14: =F4/F$11 -> 0.019505922 | G14: =G4/G$11 -> 0.088371269 | J14: 15-19 | K14: =K4/K$11 -> 0.0090308892 | L14: =L4/L$11 -> 0.0045433279 | M14: =M4/M$11 -> 0.013219511 | N14: =N4/N$11 -> 0.0048584374 | O14: =O4/O$11 -> 0.013839324
B15: 20-24 | C15: =C5/C$11 -> 0.098034674 | D15: =D5/D$11 -> 0.10207457 | E15: =E5/E$11 -> 0.14243468 | F15: =F5/F$11 -> 0.076729279 | G15: =G5/G$11 -> 0.2301567 | J15: 20-24 | K15: =K5/K$11 -> 0.07306812 | L15: =L5/L$11 -> 0.049009619 | M15: =M5/M$11 -> 0.086697225 | N15: =N5/N$11 -> 0.07039071 | O15: =O5/O$11 -> 0.087087278
B16: 25-29 | C16: =C6/C$11 -> 0.14286522 | D16: =D6/D$11 -> 0.14940747 | E16: =E6/E$11 -> 0.13625283 | F16: =F6/F$11 -> 0.13020477 | G16: =G6/G$11 -> 0.14744577 | J16: 25-29 | K16: =K6/K$11 -> 0.15153661 | L16: =L6/L$11 -> 0.12270349 | M16: =M6/M$11 -> 0.16803944 | N16: =N6/N$11 -> 0.16851145 | O16: =O6/O$11 -> 0.19032404
B17: 30-34 | C17: =C7/C$11 -> 0.18266622 | D17: =D7/D$11 -> 0.18788097 | E17: =E7/E$11 -> 0.15914084 | F17: =F7/F$11 -> 0.18358002 | G17: =G7/G$11 -> 0.184044 | J17: 30-34 | K17: =K7/K$11 -> 0.18293 | L17: =L7/L$11 -> 0.18232978 | M17: =M7/M$11 -> 0.17792028 | N17: =N7/N$11 -> 0.19729362 | O17: =O7/O$11 -> 0.17992869
B18: 35-39 | C18: =C8/C$11 -> 0.21322626 | D18: =D8/D$11 -> 0.20246262 | E18: =E8/E$11 -> 0.17602504 | F18: =F8/F$11 -> 0.21421105 | G18: =G8/G$11 -> 0.13649571 | J18: 35-39 | K18: =K8/K$11 -> 0.1830134 | L18: =L8/L$11 -> 0.20063265 | M18: =M8/M$11 -> 0.16549933 | N18: =N8/N$11 -> 0.18535338 | O18: =O8/O$11 -> 0.17635815
B19: 40-44 | C19: =C9/C$11 -> 0.19230293 | D19: =D9/D$11 -> 0.18393753 | E19: =E9/E$11 -> 0.16462966 | F19: =F9/F$11 -> 0.2140795 | G19: =G9/G$11 -> 0.14515344 | J19: 40-44 | K19: =K9/K$11 -> 0.19734 | L19: =L9/L$11 -> 0.22024152 | M19: =M9/M$11 -> 0.18241137 | N19: =N9/N$11 -> 0.1874284 | O19: =O9/O$11 -> 0.17479513
B20: 45-49 | C20: =C10/C$11 -> 0.14044789 | D20: =D10/D$11 -> 0.15489278 | E20: =E10/E$11 -> 0.12922047 | F20: =F10/F$11 -> 0.16168946 | G20: =G10/G$11 -> 0.068333114 | J20: 45-49 | K20: =K10/K$11 -> 0.20308097 | L20: =L10/L$11 -> 0.22053961 | M20: =M10/M$11 -> 0.20621284 | N20: =N10/N$11 -> 0.186164 | O20: =O10/O$11 -> 0.17766739
B21: Total | C21: =C11/C$11 -> 1 | D21: =D11/D$11 -> 1 | E21: =E11/E$11 -> 1 | F21: =F11/F$11 -> 1 | G21: =G11/G$11 -> 1 | J21: Total | K21: =K11/K$11 -> 1 | L21: =L11/L$11 -> 1 | M21: =M11/M$11 -> 1 | N21: =N11/N$11 -> 1 | O21: =O11/O$11 -> 1
B23: idade_categ | C23: adm e gestao | D23: educacao | E23: outras | F23: saude | J23: idade_categ | K23: adm_e_gestao_publica | L23: educacao | M23: outras | N23: saude
C24: =C11/SUM($C$11:$G$11) -> 0.30486717 | D24: =D11/SUM($C$11:$G$11) -> 0.53667325 | E24: =(E11+G11)/SUM($C$11:$G$11) -> 0.065552817 | F24: =F11/SUM($C$11:$G$11) -> 0.09290676 | K24: =K11/SUM($K$11:$O$11) -> 0.37226472 | L24: =L11/SUM($K$11:$O$11) -> 0.46146974 | M24: =(M11+O11)/SUM($K$11:$O$11) -> 0.033355342 | N24: =N11/SUM($K$11:$O$11) -> 0.1329102

Sheet parturição_area
A2: > | B2: svytable(~filhos_ever_born+idade_categ+ocupacao_v3, | C2: design | D2: = | E2: mulheres_2000_aux) | Q2: > | R2: svytable(~filhos_ever_born+idade_categ+ocupacao_v3, | S2: design | T2: = | U2: mulheres_2010_aux)
A3: , | B3: , | C3: ocupacao_v3 | D3: = | E3: funcionario_publico | Q3: , | R3: , | S3: ocupacao_v3 | T3: = | U3: funcionario_publico
K4: =E3 -> funcionario_publico | AA4: =U3 -> funcionario_publico
B5: idade_categ | K5: filhos_ever_born | L5: Número de mulheres de 45-49 anos | M5: Mulheres de 45-49 anos com pelo menos N filhos | N5: Razão de Perturição | O5: categ | R5: idade_categ | AA5: filhos_ever_born | AB5: Número de mulheres de 45-49 anos | AC5: Mulheres de 45-49 anos com pelo menos N filhos | AD5: Razão de Perturição | AE5: categ
A6: filhos_ever_born | C6: 15-19 | D6: 20-24 | E6: 25-29 | F6: 30-34 | G6: 35-39 | H6: 40-44 | I6: 45-49 | K6: 0 | L6: =I7 -> 37960.566 | M6: =SUM($L6:L$10) -> 249472.13 | N6: =M7/M6 -> 0.84783644 | O6: 0-1 | P6: =N6+N6*N7+N6*N7*N8+N6*N7*N8*N9 -> 2.1975468 | Q6: filhos_ever_born | S6: 15-19 | T6: 20-24 | U6: 25-29 | V6: 30-34 | W6: 35-39 | X6: 40-44 | Y6: 45-49 | AA6: 0 | AB6: =Y7 -> 64049.11 | AC6: =SUM($AB6:AB$10) -> 405195.35 | AD6: =AC7/AC6 -> 0.84193029 | AE6: 0-1 | AF6: =AD6+AD6*AD7+AD6*AD7*AD8+AD6*AD7*AD8*AD9 -> 1.8526501
B7: 0 | C7: 41345.273 | D7: 114488.49 | E7: 112067.06 | F7: 83577.635 | G7: 63920.477 | H7: 47758.979 | I7: 37960.566 | K7: 1 | L7: =I8 -> 32058.06 | M7: =SUM($L7:L$10) -> 211511.56 | N7: =M8/M7 -> 0.84843354 | O7: 1-2 | R7: 0 | S7: 11624.63 | T7: 91917.41 | U7: 155555.3 | V7: 120959.1 | W7: 79087.21 | X7: 69620.96 | Y7: 64049.11 | AA7: 1 | AB7: =Y8 -> 75909.17 | AC7: =SUM($AB7:AB$10) -> 341146.24 | AD7: =AC8/AC7 -> 0.77748789 | AE7: 1-2
B8: 1 | C8: 3898.1178 | D8: 37640.275 | E8: 65793.539 | F8: 76978.841 | G8: 66682.116 | H8: 49192.592 | I8: 32058.06 | K8: 2 | L8: =I9 -> 71446.38 | M8: =SUM($L8:L$10) -> 179453.5 | N8: =M9/M8 -> 0.6018669 | O8: 2-3 | R8: 1 | S8: 972.507 | T8: 21823.17 | U8: 74569.97 | V8: 113349.4 | W8: 100247 | X8: 87833.32 | Y8: 75909.17 | AA8: 2 | AB8: =Y9 -> 155079.5 | AC8: =SUM($AB8:AB$10) -> 265237.07 | AD8: =AC9/AC8 -> 0.4153174 | AE8: 2-3
B9: 2 | C9: 547.8282 | D9: 12206.917 | E9: 42862.476 | F9: 91601.85 | G9: 119652.09 | H9: 102898.15 | I9: 71446.38 | K9: 3 | L9: =I10 -> 58752.636 | M9: =SUM($L9:L$10) -> 108007.12 | N9: =M10/M9 -> 0.45602998 | O9: 4+ | R9: 2 | S9: 114.3296 | T9: 5488.806 | U9: 32964.41 | V9: 85835.65 | W9: 127981.2 | X9: 151986.7 | Y9: 155079.5 | AA9: 3 | AB9: =Y10 -> 76013.23 | AC9: =SUM($AB9:AB$10) -> 110157.57 | AD9: =AC10/AC9 -> 0.30995909 | AE9: 4+
B10: 3 | C10: 131.4052 | D10: 3445.3239 | E10: 14989.697 | F10: 38070.541 | G10: 59997.878 | H10: 68921.452 | I10: 58752.636 | K10: 4+ | L10: =I11 -> 49254.486 | M10: =SUM($L10:L$10) -> 49254.486 | N10: - | R10: 3 | S10: 13.69486 | T10: 1052.53 | U10: 8863.794 | V10: 28401.08 | W10: 47620.98 | X10: 64874.28 | Y10: 76013.23 | AA10: 4+ | AB10: =Y11 -> 34144.34 | AC10: =SUM($AB10:AB$10) -> 34144.34 | AD10: -
B11: 4+ | C11: 40.0898 | D11: 1144.7147 | E11: 6011.6601 | F11: 17025.995 | G11: 32178.516 | H11: 45155.812 | I11: 49254.486 | R11: 4+ | S11: 4.921647 | T11: 284.8807 | U11: 2596.864 | V11: 9683.464 | W11: 16107.39 | X11: 25803.92 | Y11: 34144.34
A15: > | B15: svytable(~filhos_ever_born+idade_categ+flag_ocup, | C15: design | D15: = | E15: mulheres_2000_aux) | Q15: > | R15: svytable(~filhos_ever_born+idade_categ+flag_ocup, | S15: design | T15: = | U15: mulheres_2000_aux)
A16: , | B16: , | C16: flag_ocup | D16: = | E16: Desocupadas | Q16: , | R16: , | S16: flag_ocup | T16: = | U16: Desocupadas
K17: =E16 -> Desocupadas
B18: idade_categ | K18: filhos_ever_born | L18: Número de mulheres de 45-49 anos | M18: Mulheres de 45-49 anos com pelo menos N filhos | N18: Razão de Perturição | O18: categ | R18: idade_categ
A19: filhos_ever_born | C19: 15-19 | D19: 20-24 | E19: 25-29 | F19: 30-34 | G19: 35-39 | H19: 40-44 | I19: 45-49 | K19: 0 | L19: =I20 -> 195949.04 | M19: =SUM($L19:L$23) -> 2329581.3 | N19: =M20/M19 -> 0.91588659 | O19: 0-1 | P19: =N19+N19*N20+N19*N20*N21+N19*N20*N21*N22 -> 2.764044 | Q19: filhos_ever_born | R19: 15-19 | S19: 20-24 | T19: 25-29 | U19: 30-34 | V19: 35-39 | W19: 40-44 | X19: 45-49 | AA19: filhos_ever_born | AB19: Número de mulheres de 45-49 anos | AC19: Mulheres de 45-49 anos com pelo menos N filhos | AD19: Razão de Perturição | AE19: categ
B20: 0 | C20: 5671376.5 | D20: 1920175.5 | E20: 716129.76 | F20: 385733.62 | G20: 272974.16 | H20: 215204.89 | I20: 195949.04 | K20: 1 | L20: =I21 -> 200851.98 | M20: =SUM($L20:L$23) -> 2133632.3 | N20: =M21/M20 -> 0.90586383 | O20: 1-2 | R20: 0 | S20: 5525438.6 | T20: 2159788.7 | U20: 988402.39 | V20: 533687.48 | W20: 354467.67 | X20: 309091.26 | Y20: 290588.74 | AA20: 0 | AB20: =Y20 -> 290588.74 | AC20: =SUM($AB20:AB$24) -> 2430425.1 | AD20: =AC21/AC20 -> 0.88043707 | AE20: 0-1 | AF20: =AD20+AD20*AD21+AD20*AD21*AD22+AD20*AD21*AD22*AD23 -> 2.3775993
B21: 1 | C21: 823093.69 | D21: 1307285.6 | E21: 898785.41 | F21: 560489.44 | G21: 364607.26 | H21: 246231.56 | I21: 200851.98 | K21: 2 | L21: =I22 -> 494077.58 | M21: =SUM($L21:L$23) -> 1932780.3 | N21: =M22/M21 -> 0.74436951 | O21: 2-3 | R21: 1 | S21: 622807.9 | T21: 1147398.4 | U21: 959343.84 | V21: 655321.7 | W21: 444132.19 | X21: 344142.56 | Y21: 295327.23 | AA21: 1 | AB21: =Y21 -> 295327.23 | AC21: =SUM($AB21:AB$24) -> 2139836.4 | AD21: =AC22/AC21 -> 0.86198607 | AE21: 1-2
B22: 2 | C22: 191265.08 | D22: 790973.33 | E22: 985676.58 | F22: 991299.01 | G22: 853253.72 | H22: 640922.03 | I22: 494077.58 | K22: 3 | L22: =I23 -> 504752.77 | M22: =SUM($L22:L$23) -> 1438702.7 | N22: =M23/M22 -> 0.64916118 | O22: 4+ | R22: 2 | S22: 107475.56 | T22: 540819.79 | U22: 802796.05 | V22: 853477.49 | W22: 790699.84 | X22: 734573.16 | Y22: 682961.15 | AA22: 2 | AB22: =Y22 -> 682961.15 | AC22: =SUM($AB22:AB$24) -> 1844509.1 | AD22: =AC23/AC22 -> 0.62973285 | AE22: 2-3
B23: 3 | C23: 33869.308 | D23: 322390.08 | E23: 547364.87 | F23: 641495.41 | G23: 653607.03 | H23: 581807.87 | I23: 504752.77 | K23: 4+ | L23: =I24 -> 933949.97 | M23: =SUM($L23:L$23) -> 933949.97 | N23: - | R23: 3 | S23: 15483.771 | T23: 182560.06 | U23: 398112.34 | V23: 499485.56 | W23: 503835.44 | X23: 516560.1 | Y23: 528864.44 | AA23: 3 | AB23: =Y23 -> 528864.44 | AC23: =SUM($AB23:AB$24) -> 1161548 | AD23: =AC24/AC23 -> 0.54468998 | AE23: 4+
B24: 4+ | C24: 7114.248 | D24: 135610.64 | E24: 374840.46 | F24: 582493.5 | G24: 740176.22 | H24: 850963.45 | I24: 933949.97 | R24: 4+ | S24: 3321.8647 | T24: 64009.542 | U24: 236204.64 | V24: 376672.98 | W24: 444849.04 | X24: 530304.38 | Y24: 632683.55 | AA24: 4+ | AB24: =Y24 -> 632683.55 | AC24: =SUM($AB24:AB$24) -> 632683.55 | AD24: -
A26: , | B26: , | C26: flag_ocup | D26: = | E26: Ocupadas | Q26: , | R26: , | S26: flag_ocup | T26: = | U26: Ocupadas
K27: =E26 -> Ocupadas
B28: idade_categ | K28: filhos_ever_born | L28: Número de mulheres de 45-49 anos | M28: Mulheres de 45-49 anos com pelo menos N filhos | N28: Razão de Perturição | O28: categ | R28: idade_categ
A29: filhos_ever_born | C29: 15-19 | D29: 20-24 | E29: 25-29 | F29: 30-34 | G29: 35-39 | H29: 40-44 | I29: 45-49 | K29: 0 | L29: =I30 -> 246970.77 | M29: =SUM($L29:L$33) -> 2180876.7 | N29: =M30/M29 -> 0.8867562 | O29: 0-1 | P29: =N29+N29*N30+N29*N30*N31+N29*N30*N31*N32 -> 2.4967892 | Q29: filhos_ever_born | R29: 15-19 | S29: 20-24 | T29: 25-29 | U29: 30-34 | V29: 35-39 | W29: 40-44 | X29: 45-49 | AA29: filhos_ever_born | AB29: Número de mulheres de 45-49 anos | AC29: Mulheres de 45-49 anos com pelo menos N filhos | AD29: Razão de Perturição | AE29: categ
B30: 0 | C30: 1932505.8 | D30: 2345583.4 | E30: 1446708.3 | F30: 822220.46 | G30: 522626.31 | H30: 348257.33 | I30: 246970.77 | K30: 1 | L30: =I31 -> 246961.73 | M30: =SUM($L30:L$33) -> 1933905.9 | N30: =M31/M30 -> 0.87229899 | O30: 1-2 | R30: 0 | S30: 1907316.4 | T30: 3068895.1 | U30: 2457948 | V30: 1396410.3 | W30: 790505.96 | X30: 588257.11 | Y30: 468838.7 | AA30: 0 | AB30: =Y30 -> 468838.7 | AC30: =SUM($AB30:AB$34) -> 3711499.7 | AD30: =AC31/AC30 -> 0.87367945 | AE30: 0-1 | AF30: =AD30+AD30*AD31+AD30*AD31*AD32+AD30*AD31*AD32*AD33 -> 2.1443669
B31: 1 | C31: 213909.11 | D31: 810523.79 | E31: 950413.58 | F31: 811363.02 | G31: 589924 | H31: 388882.82 | I31: 246961.73 | K31: 2 | L31: =I32 -> 534985.45 | M31: =SUM($L31:L$33) -> 1686944.2 | N31: =M32/M31 -> 0.68286713 | O31: 2-3 | R31: 1 | S31: 210332.64 | T31: 1016922.2 | U31: 1516732.3 | V31: 1449193.9 | W31: 1071511 | X31: 806684.26 | Y31: 593213.03 | AA31: 1 | AB31: =Y31 -> 593213.03 | AC31: =SUM($AB31:AB$34) -> 3242661 | AD31: =AC32/AC31 -> 0.81705981 | AE31: 1-2
B32: 2 | C32: 40156.505 | D32: 314054.06 | E32: 658819.82 | F32: 975674.73 | G32: 1057264.8 | H32: 827832.02 | I32: 534985.45 | K32: 3 | L32: =I33 -> 479578.23 | M32: =SUM($L32:L$33) -> 1151958.7 | N32: =M33/M32 -> 0.58368454 | O32: 4+ | R32: 2 | S32: 31596.012 | T32: 319216.86 | U32: 819842.23 | V32: 1297624 | W32: 1476653 | X32: 1443171.9 | Y32: 1227861.9 | AA32: 2 | AB32: =Y32 -> 1227861.9 | AC32: =SUM($AB32:AB$34) -> 2649448 | AD32: =AC33/AC32 -> 0.53655935 | AE32: 2-3
B33: 3 | C33: 6335.103 | D33: 105821.99 | E33: 288516.92 | F33: 519886.31 | G33: 671134.9 | H33: 644994.83 | I33: 479578.23 | K33: 4+ | L33: =I34 -> 672380.49 | M33: =SUM($L$33:L33) -> 672380.49 | N33: - | R33: 3 | S33: 4441.5461 | T33: 86113.861 | U33: 314087.15 | V33: 604490.25 | W33: 756002.55 | X33: 818089.05 | Y33: 776463.85 | AA33: 3 | AB33: =Y33 -> 776463.85 | AC33: =SUM($AB33:AB$34) -> 1421586.1 | AD33: =AC34/AC33 -> 0.45380454 | AE33: 4+
B34: 4+ | C34: 1669.483 | D34: 42057.04 | E34: 165936.7 | F34: 373861.54 | G34: 579209.93 | H34: 689012.2 | I34: 672380.49 | R34: 4+ | S34: 965.6326 | T34: 27473.903 | U34: 150658.46 | V34: 360171.79 | W34: 488357.18 | X34: 597651.59 | Y34: 645122.22 | AA34: 4+ | AB34: =Y34 -> 645122.22 | AC34: =SUM($AB$34:AB34) -> 645122.22 | AD34: -
A41: > | B41: svytable(~filhos_ever_born+idade_categ+sub_grupo_cnae, | C41: design | D41: = | E41: mulheres_func_pub_aux) | Q41: > | R41: svytable(~filhos_ever_born+idade_categ+sub_grupo_cnae, | S41: design | T41: = | U41: mulheres_func_pub_aux)
A42: , | B42: , | C42: sub_grupo_cnae | D42: = | E42: adm_e_gestao_publica | Q42: , | R42: , | S42: sub_grupo_cnae | T42: = | U42: adm_e_gestao_publica
K43: =E42 -> adm_e_gestao_publica | AA43: =U42 -> adm_e_gestao_publica
B44: idade_categ | K44: filhos_ever_born | L44: Número de mulheres de 45-49 anos | M44: Mulheres de 45-49 anos com pelo menos N filhos | N44: Razão de Perturição | O44: categ | R44: idade_categ | AA44: filhos_ever_born | AB44: Número de mulheres de 45-49 anos | AC44: Mulheres de 45-49 anos com pelo menos N filhos | AD44: Razão de Perturição | AE44: categ
A45: filhos_ever_born | B45: 15-19 | D45: 20-24 | E45: 25-29 | F45: 30-34 | G45: 35-39 | H45: 40-44 | I45: 45-49 | K45: 0 | L45: =I46 -> 11861.199 | M45: =SUM($L45:L$49) -> 71493.046 | N45: =M46/M45 -> 0.83409297 | O45: 0-1 | P45: =N45+N45*N46+N45*N46*N47+N45*N46*N47*N48 -> 2.1483064 | Q45: filhos_ever_born | R45: 15-19 | S45: 20-24 | T45: 25-29 | U45: 30-34 | V45: 35-39 | W45: 40-44 | X45: 45-49 | AA45: 0 | AB45: =Y46 -> 23513.084 | AC45: =SUM($AB45:AB$49) -> 146847.8 | AD45: =AC46/AC45 -> 0.83988126 | AE45: 0-1 | AF45: =AD45+AD45*AD46+AD45*AD46*AD47+AD45*AD46*AD47*AD48 -> 1.8285165
B46: 0 | C46: 14009.261 | D46: 33346.162 | E46: 34009.397 | F46: 26200.658 | G46: 21385.228 | H46: 15566.82 | I46: 11861.199 | K46: 1 | L46: =I47 -> 10331.06 | M46: =SUM($L46:L$49) -> 59631.847 | N46: =M47/M46 -> 0.82675264 | O46: 1-2 | R46: 0 | S46: 5964.061 | T46: 40658.528 | U46: 64329.496 | V46: 47985.174 | W46: 28837.416 | X46: 24592.974 | Y46: 23513.084 | AA46: 1 | AB46: =Y47 -> 29067.78 | AC46: =SUM($AB46:AB$49) -> 123334.71 | AD46: =AC47/AC46 -> 0.76431793 | AE46: 1-2
B47: 1 | C47: 1241.2717 | D47: 11027.547 | E47: 19037.078 | F47: 23146.302 | G47: 21294.742 | H47: 16579.628 | I47: 10331.06 | K47: 2 | L47: =I48 -> 19196.317 | M47: =SUM($L47:L$49) -> 49300.787 | N47: =M48/M47 -> 0.61062859 | O47: 2-3 | R47: 1 | S47: 494.85517 | T47: 9247.817 | U47: 28121.904 | V47: 40529.422 | W47: 36010.362 | X47: 31949.806 | Y47: 29067.78 | AA47: 2 | AB47: =Y48 -> 55513.08 | AC47: =SUM($AB47:AB$49) -> 94266.932 | AD47: =AC48/AC47 -> 0.4111076 | AE47: 2-3
B48: 2 | C48: 180.75991 | D48: 4124.6051 | E48: 12465.311 | F48: 26511.09 | G48: 37194.896 | H48: 31539.776 | I48: 19196.317 | K48: 3 | L48: =I49 -> 15552.605 | M48: =SUM($L48:L$49) -> 30104.47 | N48: =M49/M48 -> 0.4833789 | O48: 4+ | R48: 2 | S48: 57.622587 | T48: 2334.1143 | U48: 12656.038 | V48: 29640.74 | W48: 45213.442 | X48: 54278.002 | Y48: 55513.08 | AA48: 3 | AB48: =Y49 -> 26595.723 | AC48: =SUM($AB48:AB$49) -> 38753.853 | AD48: =AC49/AC48 -> 0.31372698 | AE48: 4+
B49: 3 | C49: 72.313831 | D49: 1084.909 | E49: 5062.6415 | F49: 11340.23 | G49: 17778.425 | H49: 19583.737 | I49: 15552.605 | K49: 4+ | L49: =I50 -> 14551.866 | M49: =SUM($L49:L$49) -> 14551.866 | N49: - | R49: 3 | S49: 13.694856 | T49: 467.03928 | U49: 3429.5806 | V49: 10349.921 | W49: 15992.525 | X49: 22227.317 | Y49: 26595.723 | AA49: 4+ | AB49: =Y50 -> 12158.129 | AC49: =SUM($AB49:AB$49) -> 12158.129 | AD49: -
B50: 4+ | C50: 0 | D50: 319.964 | E50: 2149.1285 | F50: 5785.4206 | G50: 10886.572 | H50: 14619.168 | I50: 14551.866 | R50: 4+ | S50: 0 | T50: 128.0396 | U50: 1039.0624 | V50: 3771.38 | W50: 6283.1989 | X50: 9648.4036 | Y50: 12158.129
A52: , | B52: , | C52: sub_grupo_cnae | D52: = | E52: educacao | Q52: , | R52: , | S52: sub_grupo_cnae | T52: = | U52: educacao
...

Sheet TFT_area_atuacao
A1: idade media a fecundidade e TFT
A2: > | B2: svytable(~idade_categ+flag_nasc_12m+ocupacao_v3, | C2: design | D2: = | E2: mulheres_2000_aux) | J2: > | K2: svytable(~idade_categ+V6664+ocupacao_v3, | L2: design | M2: = | N2: mulheres_2010_aux)
A3: , | B3: , | C3: ocupacao_v3 | D3: = | E3: funcionario_publico | J3: , | K3: , | L3: ocupacao_v3 | M3: = | N3: funcionario_publico
B5: flag_nasc_12m | F5: =E3 -> funcionario_publico | K5: V6664 | O5: =N3 -> funcionario_publico
A6: idade_categ | C6: 0 | D6: 1 | E6: total mulheres | F6: TEF | G6: ponto_medio | J6: idade_categ | L6: Não | M6: Sim | N6: total mulheres | O6: TEF | P6: ponto_medio
B7: 15-19 | C7: 2972.75 | D7: 1644.691 | E7: 45962.714 | F7: =D7/E7 -> 0.035783157 | G7: 17.5 | H7: =G7*F7 -> 0.62620525 | K7: 15-19 | L7: 12444.65 | M7: 285.4266 | N7: =SUM(L7:M7) -> 12730.077 | O7: =M7/N7 -> 0.022421436 | P7: 17.5 | Q7: =P7*O7 -> 0.39237513
B8: 20-24 | C8: 41806.58 | D8: 12630.65 | E8: 168925.72 | F8: =D8/E8 -> 0.074770436 | G8: 22.5 | H8: =G8*F8 -> 1.6823348 | K8: 20-24 | L8: 114958.4 | M8: 5608.359 | N8: =SUM(L8:M8) -> 120566.76 | O8: =M8/N8 -> 0.046516627 | P8: 22.5 | Q8: =P8*O8 -> 1.0466241
B9: 25-29 | C9: 110077.6 | D9: 19579.8 | E9: 241724.43 | F9: =D9/E9 -> 0.0810005 | G9: 27.5 | H9: =G9*F9 -> 2.2275137 | K9: 25-29 | L9: 256529.7 | M9: 18020.59 | N9: =SUM(L9:M9) -> 274550.29 | O9: =M9/N9 -> 0.065636755 | P9: 27.5 | Q9: =P9*O9 -> 1.8050108
B10: 30-34 | C10: 203675.5 | D10: 20001.68 | E10: 307254.86 | F10: =D10/E10 -> 0.06509801 | G10: 32.5 | H10: =G10*F10 -> 2.1156853 | K10: 30-34 | L10: 333431.4 | M10: 24797.33 | N10: =SUM(L10:M10) -> 358228.73 | O10: =M10/N10 -> 0.069222058 | P10: 32.5 | Q10: =P10*O10 -> 2.2497169
B11: 35-39 | C11: 267110.9 | D11: 11399.68 | E11: 342431.08 | F11: =D11/E11 -> 0.033290437 | G11: 37.5 | H11: =G11*F11 -> 1.2483914 | K11: 35-39 | L11: 355090.6 | M11: 15953.15 | N11: =SUM(L11:M11) -> 371043.75 | O11: =M11/N11 -> 0.042995334 | P11: 37.5 | Q11: =P11*O11 -> 1.612325
B12: 40-44 | C12: 262982.7 | D12: 3185.282 | E12: 313926.99 | F12: =D12/E12 -> 0.010146569 | G12: 42.5 | H12: =G12*F12 -> 0.4312292 | K12: 40-44 | L12: 395488.6 | M12: 4630.552 | N12: =SUM(L12:M12) -> 400119.15 | O12: =M12/N12 -> 0.011572933 | P12: 42.5 | Q12: =P12*O12 -> 0.49184964
B13: 45-49 | C13: 211198 | D13: 313.532 | E13: 249472.13 | F13: =D13/E13 -> 0.0012567817 | G13: 47.5 | H13: =G13*F13 -> 0.05969713 | K13: 45-49 | L13: 404668.9 | M13: 526.4428 | N13: =SUM(L13:M13) -> 405195.34 | O13: =M13/N13 -> 0.0012992321 | P13: 47.5 | Q13: =P13*O13 -> 0.061713525
F14: =SUM(F7:F13)*5 -> 1.5067295 | H14: =SUM(H7:H13)/SUM(F7:F13) -> 27.845267 | O14: =SUM(O7:O13)*5 -> 1.2983219 | Q14: =SUM(Q7:Q13)/SUM(O7:O13) -> 29.498136
A17: Por area de atuacao
B18: flag_nasc_12m | F18: =E16 -> 0 | O18: V6664 | S18: =R16 -> 0
A19: idade_categ | B19: 0 | C19: 1 | E19: adm_e_gestao_publica | F19: TEF | G19: ponto_medio | N19: idade_categ | P19: Não | Q19: Sim | S19: TEF | T19: ponto_medio
B20: 15-19 | C20: 1025.021 | D20: 469.3243 | E20: 15503.606 | F20: =D20/E20 -> 0.030271944 | G20: 17.5 | H20: =G20*F20 -> 0.52975902 | O20: 15-19 | P20: 6358.16 | Q20: 172.0731 | R20: =SUM(P20:Q20) -> 6530.2331 | S20: =Q20/R20 -> 0.026350223 | T20: 17.5 | U20: =T20*S20 -> 0.46112891
B21: 20-24 | C21: 12801.44 | D21: 3755.581 | E21: 49903.187 | F21: =D21/E21 -> 0.075257338 | G21: 22.5 | H21: =G21*F21 -> 1.6932901 | O21: 20-24 | P21: 50502.53 | Q21: 2333.009 | R21: =SUM(P21:Q21) -> 52835.539 | S21: =Q21/R21 -> 0.044156056 | T21: 22.5 | U21: =T21*S21 -> 0.99351125
B22: 25-29 | C22: 33399.16 | D22: 5315 | E22: 72723.555 | F22: =D22/E22 -> 0.073084986 | G22: 27.5 | H22: =G22*F22 -> 2.0098371 | O22: 25-29 | P22: 102871.5 | Q22: 6704.572 | R22: =SUM(P22:Q22) -> 109576.07 | S22: =Q22/R22 -> 0.06118646 | T22: 27.5 | U22: =T22*S22 -> 1.6826277
B23: 30-34 | C23: 61047.93 | D23: 5735.114 | E23: 92983.7 | F23: =D23/E23 -> 0.061678703 | G23: 32.5 | H23: =G23*F23 -> 2.0045578 | O23: 30-34 | P23: 123348.6 | Q23: 8928.053 | R23: =SUM(P23:Q23) -> 132276.65 | S23: =Q23/R23 -> 0.067495305 | T23: 32.5 | U23: =T23*S23 -> 2.1935974
B24: 35-39 | C24: 83545.55 | D24: 3609.082 | E24: 108539.86 | F24: =D24/E24 -> 0.033251212 | G24: 37.5 | H24: =G24*F24 -> 1.2469205 | O24: 35-39 | P24: 126399.5 | Q24: 5937.441 | R24: =SUM(P24:Q24) -> 132336.94 | S24: =Q24/R24 -> 0.044866089 | T24: 37.5 | U24: =T24*S24 -> 1.6824783
B25: 40-44 | C25: 81188.72 | D25: 1133.588 | E25: 97889.13 | F25: =D25/E25 -> 0.011580326 | G25: 42.5 | H25: =G25*F25 -> 0.49216384 | O25: 40-44 | P25: 140994.5 | Q25: 1701.962 | R25: =SUM(P25:Q25) -> 142696.46 | S25: =Q25/R25 -> 0.011927149 | T25: 42.5 | U25: =T25*S25 -> 0.50690384
B26: 45-49 | C26: 59555.55 | D26: 76.30204 | E26: 71493.046 | F26: =D26/E26 -> 0.0010672652 | G26: 47.5 | H26: =G26*F26 -> 0.050695097 | O26: 45-49 | P26: 146602.4 | Q26: 245.444 | R26: =SUM(P26:Q26) -> 146847.84 | S26: =Q26/R26 -> 0.0016714171 | T26: 47.5 | U26: =T26*S26 -> 0.079392313
F27: =SUM(F20:F26)*5 -> 1.4309589 | H27: =SUM(H20:H26)/SUM(F20:F26) -> 28.048407 | S27: =SUM(S20:S26)*5 -> 1.2882635 | U27: =SUM(U20:U26)/SUM(S20:S26) -> 29.495673
A28: , | B28: , | C28: sub_grupo_cnae | D28: = | E28: educacao | N28: , | O28: , | P28: sub_grupo_cnae | Q28: = | R28: educacao
B30: flag_nasc_12m | F30: =E28 -> educacao | O30: V6664 | S30: =R28 -> educacao
A31: idade_categ | B31: 0 | C31: 1 | E31: educacao | F31: TEF | G31: ponto_medio | N31: idade_categ | P31: Não | Q31: Sim | S31: TEF | T31: ponto_medio
B32: 15-19 | C32: 1138.838 | D32: 645.7247 | E32: 17333.867 | F32: =D32/E32 -> 0.037252202 | G32: 17.5 | H32: =G32*F32 -> 0.65191353 | O32: 15-19 | P32: 4001.335 | Q32: 71.18918 | R32: =SUM(P32:Q32) -> 4072.5242 | S32: =Q32/R32 -> 0.017480358 | T32: 17.5 | U32: =T32*S32 -> 0.30590626
B33: 20-24 | C33: 21528.67 | D33: 7021.458 | E33: 91467.208 | F33: =D33/E33 -> 0.076764757 | G33: 22.5 | H33: =G33*F33 -> 1.727207 | O33: 20-24 | P33: 41720.04 | Q33: 2210.939 | R33: =SUM(P33:Q33) -> 43930.979 | S33: =Q33/R33 -> 0.05032756 | T33: 22.5 | U33: =T33*S33 -> 1.1323701
B34: 25-29 | C34: 60666.92 | D34: 11545.36 | E34: 133881.38 | F34: =D34/E34 -> 0.086235744 | G34: 27.5 | H34: =G34*F34 -> 2.3714829 | O34: 25-29 | P34: 101915 | Q34: 8073.3 | R34: =SUM(P34:Q34) -> 109988.3 | S34: =Q34/R34 -> 0.073401444 | T34: 27.5 | U34: =T34*S34 -> 2.0185397
B35: 30-34 | C35: 111282.4 | D35: 11372.51 | E35: 168356.79 | F35: =D35/E35 -> 0.067550051 | G35: 32.5 | H35: =G35*F35 -> 2.1953766 | O35: 30-34 | P35: 151739.4 | Q35: 11696.43 | R35: =SUM(P35:Q35) -> 163435.83 | S35: =Q35/R35 -> 0.071565886 | T35: 32.5 | U35: =T35*S35 -> 2.3258913
B36: 35-39 | C36: 141495.8 | D36: 6192.974 | E36: 181423.15 | F36: =D36/E36 -> 0.034135522 | G36: 37.5 | H36: =G36*F36 -> 1.2800821 | O36: 35-39 | P36: 172288.5 | Q36: 7553.468 | R36: =SUM(P36:Q36) -> 179841.97 | S36: =Q36/R36 -> 0.042000586 | T36: 37.5 | U36: =T36*S36 -> 1.575022
B37: 40-44 | C37: 138753.4 | D37: 1463.971 | E37: 164823.15 | F37: =D37/E37 -> 0.0088820717 | G37: 42.5 | H37: =G37*F37 -> 0.37748805 | O37: 40-44 | P37: 195293.8 | Q37: 2125.148 | R37: =SUM(P37:Q37) -> 197418.95 | S37: =Q37/R37 -> 0.010764661 | T37: 42.5 | U37: =T37*S37 -> 0.45749808
B38: 45-49 | C38: 118262.8 | D38: 178.6733 | E38: 138796.67 | F38: =D38/E38 -> 0.0012873025 | G38: 47.5 | H38: =G38*F38 -> 0.06114687 | O38: 45-49 | P38: 197488.4 | Q38: 197.6931 | R38: =SUM(P38:Q38) -> 197686.09 | S38: =Q38/R38 -> 0.0010000354 | T38: 47.5 | U38: =T38*S38 -> 0.047501684
F39: =SUM(F32:F38)*5 -> 1.5605383 | H39: =SUM(H32:H38)/SUM(F32:F38) -> 27.761887 | S39: =SUM(S32:S38)*5 -> 1.3327026 | U39: =SUM(U32:U38)/SUM(S32:S38) -> 29.499188
A40: , | B40: , | C40: sub_grupo_cnae | D40: = | E40: outras | N40: , | O40: , | P40: sub_grupo_cnae | Q40: = | R40: outras
B42: flag_nasc_12m | F42: =E40 -> outras | O42: V6664 | S42: =R40 -> outras
A43: idade_categ | C43: 0 | D43: 1 | E43: outras | F43: TEF | G43: ponto_medio | N43: idade_categ | P43: Não | Q43: Sim | S43: TEF | T43: ponto_medio
B44: 15-19 | C44: 642.71474 | D44: 454.90736 | E44: 10099.36 | F44: =D44/E44 -> 0.045043187 | G44: 17.5 | H44: =G44*F44 -> 0.78825577 | O44: 15-19 | P44: 866.7816 | Q44: 6.242038 | R44: =SUM(P44:Q44) -> 873.02364 | S44: =Q44/R44 -> 0.0071499072 | T44: 17.5 | U44: =T44*S44 -> 0.12512338
B45: 20-24 | C45: 4388.8339 | D45: 966.16242 | E45: 15652.61 | F45: =D45/E45 -> 0.061725324 | G45: 22.5 | H45: =G45*F45 -> 1.3888198 | O45: 20-24 | P45: 5473.781 | Q45: 153.779 | R45: =SUM(P45:Q45) -> 5627.56 | S45: =Q45/R45 -> 0.027326052 | T45: 22.5 | U45: =T45*S45 -> 0.61483618
...

Sheet parturição
A1: > | B1: svytable(~filhos_ever_born+idade_categ+ocupacao_v3, | C1: design | D1: = | E1: mulheres_2000_aux) | Q1: > | R1: svytable(~filhos_ever_born+idade_categ+ocupacao_v3, | S1: design | T1: = | U1: mulheres_2010_aux)
A2: , | B2: , | C2: ocupacao_v3 | D2: = | E2: funcionario_publico | Q2: , | R2: , | S2: ocupacao_v3 | T2: = | U2: funcionario_publico
K3: =E2 -> funcionario_publico | AA3: =U2 -> funcionario_publico
B4: idade_categ | K4: filhos_ever_born | L4: Número de mulheres de 45-49 anos | M4: Mulheres de 45-49 anos com pelo menos N filhos | N4: Razão de Perturição | O4: categ | R4: idade_categ | AA4: filhos_ever_born | AB4: Número de mulheres de 45-49 anos | AC4: Mulheres de 45-49 anos com pelo menos N filhos | AD4: Razão de Perturição | AE4: categ
A5: filhos_ever_born | C5: 15-19 | D5: 20-24 | E5: 25-29 | F5: 30-34 | G5: 35-39 | H5: 40-44 | I5: 45-49 | K5: 0 | L5: =I6 -> 37356.07 | M5: =SUM($L5:L$9) -> 249472.13 | N5: =M6/M5 -> 0.85025955 | O5: 0-1 | P5: =N5+N5*N6+N5*N6*N7+N5*N6*N7*N8 -> 2.2518034 | Q5: filhos_ever_born | R5: 15-19 | S5: 20-24 | T5: 25-29 | U5: 30-34 | V5: 35-39 | W5: 40-44 | X5: 45-49 | AA5: 0 | AB5: =Y6 -> 64049.11 | AC5: =SUM($AB5:AB$9) -> 405195.35 | AD5: =AC6/AC5 -> 0.84193029 | AE5: 0-1 | AF5: =AD5+AD5*AD6+AD5*AD6*AD7+AD5*AD6*AD7*AD8 -> 1.8526501
B6: 0 | C6: 41234.72 | D6: 114072.9 | E6: 111359.1 | F6: 82902.81 | G6: 63317.51 | H6: 47140.2 | I6: 37356.07 | K6: 1 | L6: =I7 -> 30471.29 | M6: =SUM($L6:L$9) -> 212116.06 | N6: =M7/M6 -> 0.85634614 | O6: 1-2 | R6: 0 | S6: 11624.63 | T6: 91917.41 | U6: 155555.3 | V6: 120959.1 | W6: 79087.21 | X6: 69620.96 | Y6: 64049.11 | AA6: 1 | AB6: =Y7 -> 75909.17 | AC6: =SUM($AB6:AB$9) -> 341146.24 | AD6: =AC7/AC6 -> 0.77748789 | AE6: 1-2
B7: 1 | C7: 3925.528 | D7: 37069.92 | E7: 64614.05 | F7: 75049.42 | G7: 64449.51 | H7: 47157.51 | I7: 30471.29 | K7: 2 | L7: =I8 -> 68292.29 | M7: =SUM($L7:L$9) -> 181644.77 | N7: =M8/M7 -> 0.62403382 | O7: 2-3 | R7: 1 | S7: 972.507 | T7: 21823.17 | U7: 74569.97 | V7: 113349.4 | W7: 100247 | X7: 87833.32 | Y7: 75909.17 | AA7: 2 | AB7: =Y8 -> 155079.5 | AC7: =SUM($AB7:AB$9) -> 265237.07 | AD7: =AC8/AC7 -> 0.4153174 | AE7: 2-3
B8: 2 | C8: 597.333 | D8: 12516.01 | E8: 42723.97 | F8: 89770.61 | G8: 116333.9 | H8: 99274.69 | I8: 68292.29 | K8: 3 | L8: =I9 -> 58703.61 | M8: =SUM($L8:L$9) -> 113352.48 | N8: =M9/M8 -> 0.48211446 | O8: 4+ | R8: 2 | S8: 114.3296 | T8: 5488.806 | U8: 32964.41 | V8: 85835.65 | W8: 127981.2 | X8: 151986.7 | Y8: 155079.5 | AA8: 3 | AB8: =Y9 -> 76013.23 | AC8: =SUM($AB8:AB$9) -> 110157.57 | AD8: =AC9/AC8 -> 0.30995909 | AE8: 4+
B9: 3 | C9: 156.4834 | D9: 3819.09 | E9: 15801.37 | F9: 39522.27 | G9: 61372.87 | H9: 69376.19 | I9: 58703.61 | K9: 4+ | L9: =I10 -> 54648.87 | M9: =SUM($L9:L$9) -> 54648.87 | N9: - | R9: 3 | S9: 13.69486 | T9: 1052.53 | U9: 8863.794 | V9: 28401.08 | W9: 47620.98 | X9: 64874.28 | Y9: 76013.23 | AA9: 4+ | AB9: =Y10 -> 34144.34 | AC9: =SUM($AB9:AB$9) -> 34144.34 | AD9: -
B10: 4+ | C10: 48.65119 | D10: 1447.822 | E10: 7225.966 | F10: 20009.75 | G10: 36957.3 | H10: 50978.39 | I10: 54648.87 | R10: 4+ | S10: 4.921647 | T10: 284.8807 | U10: 2596.864 | V10: 9683.464 | W10: 16107.39 | X10: 25803.92 | Y10: 34144.34
A12: , | B12: , | C12: ocupacao_v3 | D12: = | E12: informal | Q12: , | R12: , | S12: ocupacao_v3 | T12: = | U12: informal
K13: =E12 -> informal | AA13: =U12 -> informal
B14: idade_categ | K14: filhos_ever_born | L14: Número de mulheres de 45-49 anos | M14: Mulheres de 45-49 anos com pelo menos N filhos | N14: Razão de Perturição | O14: categ | R14: idade_categ | AA14: filhos_ever_born | AB14: Número de mulheres de 45-49 anos | AC14: Mulheres de 45-49 anos com pelo menos N filhos | AD14: Razão de Perturição | AE14: categ
A15: filhos_ever_born | C15: 15-19 | D15: 20-24 | E15: 25-29 | F15: 30-34 | G15: 35-39 | H15: 40-44 | I15: 45-49 | K15: 0 | L15: =I16 -> 67889.41 | M15: =SUM($L15:L$19) -> 830843.28 | N15: =M16/M15 -> 0.91828855 | O15: 0-1 | P15: =N15+N15*N16+N15*N16*N17+N15*N16*N17*N18 -> 2.7841078 | Q15: filhos_ever_born | R15: 15-19 | S15: 20-24 | T15: 25-29 | U15: 30-34 | V15: 35-39 | W15: 40-44 | X15: 45-49 | AA15: 0 | AB15: =Y16 -> 126757.9 | AC15: =SUM($AB15:AB$19) -> 1314694.6 | AD15: =AC16/AC15 -> 0.90358377 | AE15: 0-1 | AF15: =AD15+AD15*AD16+AD15*AD16*AD17+AD15*AD16*AD17*AD18 -> 2.3926567
B16: 0 | C16: 1135867 | D16: 898915.2 | E16: 428876.8 | F16: 220521.9 | G16: 137808.9 | H16: 88883.45 | I16: 67889.41 | K16: 1 | L16: =I17 -> 75356.17 | M16: =SUM($L16:L$19) -> 762953.87 | N16: =M17/M16 -> 0.90123103 | O16: 1-2 | R16: 0 | S16: 925265.1 | T16: 958425.6 | U16: 603180.2 | V16: 328413 | W16: 203850.8 | X16: 156913.5 | Y16: 126757.9 | AA16: 1 | AB16: =Y17 -> 169554.6 | AC16: =SUM($AB16:AB$19) -> 1187936.7 | AD16: =AC17/AC16 -> 0.85726967 | AE16: 1-2
B17: 1 | C17: 132728.5 | D17: 372207.6 | E17: 347015.7 | F17: 256344.7 | G17: 175251 | H17: 114716.3 | I17: 75356.17 | K17: 2 | L17: =I18 -> 167921.5 | M17: =SUM($L17:L$19) -> 687597.7 | N17: =M18/M17 -> 0.75578525 | O17: 2-3 | R17: 1 | S17: 114518.9 | T17: 409108.1 | U17: 494093.5 | V17: 416307.5 | W17: 306223.6 | X17: 231607.9 | Y17: 169554.6 | AA17: 2 | AB17: =Y18 -> 396809.4 | AC17: =SUM($AB17:AB$19) -> 1018382.1 | AD17: =AC18/AC17 -> 0.61035313 | AE17: 2-3
B18: 2 | C18: 28385.61 | D18: 182139.5 | E18: 310673.3 | F18: 391395.2 | G18: 369756.2 | H18: 266484.4 | I18: 167921.5 | K18: 3 | L18: =I19 -> 176746.7 | M18: =SUM($L18:L$19) -> 519676.2 | N18: =M19/M18 -> 0.65989072 | O18: 4+ | R18: 2 | S18: 17785.69 | T18: 156401.8 | U18: 351495.7 | V18: 501839.1 | W18: 531388.3 | X18: 494933.9 | Y18: 396809.4 | AA18: 3 | AB18: =Y19 -> 303851.3 | AC18: =SUM($AB18:AB$19) -> 621572.7 | AD18: =AC19/AC18 -> 0.51115726 | AE18: 4+
B19: 3 | C19: 5024.295 | D19: 69508.52 | E19: 167116 | F19: 256901.2 | G19: 297312.3 | H19: 255556.3 | I19: 176746.7 | K19: 4+ | L19: =I20 -> 342929.5 | M19: =SUM($L19:L$19) -> 342929.5 | N19: - | R19: 3 | S19: 2470.977 | T19: 46684.46 | U19: 161301.9 | V19: 285471.1 | W19: 333553.7 | X19: 341050.8 | Y19: 303851.3 | AA19: 4+ | AB19: =Y20 -> 317721.4 | AC19: =SUM($AB19:AB$19) -> 317721.4 | AD19: -
B20: 4+ | C20: 1385.306 | D20: 31105.4 | E20: 113449.1 | F20: 235466.5 | G20: 333519.7 | H20: 372193.5 | I20: 342929.5 | R20: 4+ | S20: 495.4837 | T20: 14958.3 | U20: 84281.15 | V20: 194715.5 | W20: 254700.2 | X20: 301306.5 | Y20: 317721.4
A22: , | B22: , | C22: ocupacao_v3 | D22: = | E22: militar | Q22: , | R22: , | S22: ocupacao_v3 | T22: = | U22: militar
K23: =E22 -> militar | AA23: =U22 -> militar
B24: idade_categ | K24: filhos_ever_born | L24: Número de mulheres de 45-49 anos | M24: Mulheres de 45-49 anos com pelo menos N filhos | N24: Razão de Perturição | O24: categ | R24: idade_categ | AA24: filhos_ever_born | AB24: Número de mulheres de 45-49 anos | AC24: Mulheres de 45-49 anos com pelo menos N filhos | AD24: Razão de Perturição | AE24: categ
A25: filhos_ever_born | C25: 15-19 | D25: 20-24 | E25: 25-29 | F25: 30-34 | G25: 35-39 | H25: 40-44 | I25: 45-49 | K25: 0 | L25: =I26 -> 28.54341 | M25: =SUM($L25:L$29) -> 219.8084 | N25: =M26/M25 -> 0.87014413 | O25: 0-1 | P25: =N25+N25*N26+N25*N26*N27+N25*N26*N27*N28 -> 2.1258335 | Q25: filhos_ever_born | R25: 15-19 | S25: 20-24 | T25: 25-29 | U25: 30-34 | V25: 35-39 | W25: 40-44 | X25: 45-49 | AA25: 0 | AB25: =Y26 -> 382.9348 | AC25: =SUM($AB25:AB$29) -> 1882.3039 | AD25: =AC26/AC25 -> 0.79656058 | AE25: 0-1 | AF25: =AD25+AD25*AD26+AD25*AD26*AD27+AD25*AD26*AD27*AD28 -> 1.5175968
B26: 0 | C26: 346.6606 | D26: 3047.33 | E26: 3175.89 | F26: 1553.944 | G26: 598.3126 | H26: 120.3378 | I26: 28.54341 | K26: 1 | L26: =I27 -> 12.58872 | M26: =SUM($L26:L$29) -> 191.26499 | N26: =M27/M26 -> 0.93418179 | O26: 1-2 | R26: 0 | S26: 402.1327 | T26: 3603.444 | U26: 4799.409 | V26: 2656.769 | W26: 1249.995 | X26: 707.2182 | Y26: 382.9348 | AA26: 1 | AB26: =Y27 -> 521.9636 | AC26: =SUM($AB26:AB$29) -> 1499.3691 | AD26: =AC27/AC26 -> 0.65187784 | AE26: 1-2
B27: 1 | C27: 0 | D27: 630.4508 | E27: 1996.172 | F27: 1567.536 | G27: 741.9814 | H27: 116.9799 | I27: 12.58872 | K27: 2 | L27: =I28 -> 121.3739 | M27: =SUM($L27:L$29) -> 178.67627 | N27: =M28/M27 -> 0.32070498 | O27: 2-3 | R27: 1 | S27: 30.36255 | T27: 290.2468 | U27: 1091.765 | V27: 2146.646 | W27: 1479.498 | X27: 1141.247 | Y27: 521.9636 | AA27: 2 | AB27: =Y28 -> 671.0447 | AC27: =SUM($AB27:AB$29) -> 977.40546 | AD27: =AC28/AC27 -> 0.31344286 | AE27: 2-3
B28: 2 | C28: 8.897209 | D28: 142.0361 | E28: 797.8831 | F28: 1465.173 | G28: 920.6428 | H28: 190.3312 | I28: 121.3739 | K28: 3 | L28: =I29 -> 17.26995 | M28: =SUM($L28:L$29) -> 57.30237 | N28: =M29/M28 -> 0.69861718 | O28: 4+ | R28: 2 | S28: 0 | T28: 63.75169 | U28: 230.3775 | V28: 1090.683 | W28: 1641.036 | X28: 1712.231 | Y28: 671.0447 | AA28: 3 | AB28: =Y29 -> 232.9177 | AC28: =SUM($AB28:AB$29) -> 306.36076 | AD28: =AC29/AC28 -> 0.23972737 | AE28: 4+
B29: 3 | C29: 0 | D29: 8.334719 | E29: 132.9649 | F29: 443.5521 | G29: 325.7858 | H29: 78.28884 | I29: 17.26995 | K29: 4+ | L29: =I30 -> 40.03242 | M29: =SUM($L29:L$29) -> 40.03242 | N29: - | R29: 3 | S29: 0 | T29: 0 | U29: 11.27755 | V29: 247.6074 | W29: 429.5437 | X29: 592.9464 | Y29: 232.9177 | AA29: 4+ | AB29: =Y30 -> 73.44306 | AC29: =SUM($AB29:AB$29) -> 73.44306 | AD29: -
B30: 4+ | C30: 0 | D30: 0 | E30: 41.429 | F30: 107.5041 | G30: 76.42543 | H30: 25.1397 | I30: 40.03242 | R30: 4+ | S30: 0 | T30: 0 | U30: 0 | V30: 61.65615 | W30: 19.36239 | X30: 88.5488 | Y30: 73.44306
A32: , | B32: , | C32: ocupacao_v3 | D32: = | E32: proprio_consumo | Q32: , | R32: , | S32: ocupacao_v3 | T32: = | U32: proprio_consumo
K33: =E32 -> proprio_consumo | AA33: =U32 -> proprio_consumo
B34: idade_categ | K34: filhos_ever_born | L34: Número de mulheres de 45-49 anos | M34: Mulheres de 45-49 anos com pelo menos N filhos | N34: Razão de Perturição | O34: categ | R34: idade_categ | AA34: filhos_ever_born | AB34: Número de mulheres de 45-49 anos | AC34: Mulheres de 45-49 anos com pelo menos N filhos | AD34: Razão de Perturição | AE34: categ
A35: filhos_ever_born | C35: 15-19 | D35: 20-24 | E35: 25-29 | F35: 30-34 | G35: 35-39 | H35: 40-44 | I35: 45-49 | K35: 0 | L35: =I36 -> 4071.864 | M35: =SUM($L35:L$39) -> 60386.354 | N35: =M36/M35 -> 0.9325698 | O35: 0-1 | P35: =N35+N35*N36+N35*N36*N37+N35*N36*N37*N38 -> 3.3549317 | Q35: filhos_ever_born | R35: 15-19 | S35: 20-24 | T35: 25-29 | U35: 30-34 | V35: 35-39 | W35: 40-44 | X35: 45-49 | AA35: 0 | AB35: =Y36 -> 9837.647 | AC35: =SUM($AB35:AB$39) -> 133638.07 | AD35: =AC36/AC35 -> 0.9263859 | AE35: 0-1 | AF35: =AD35+AD35*AD36+AD35*AD36*AD37+AD35*AD36*AD37*AD38 -> 2.9563321
B36: 0 | C36: 35297.28 | D36: 16002.13 | E36: 7528.041 | F36: 5205.017 | G36: 3850.273 | H36: 3964.619 | I36: 4071.864 | K36: 1 | L36: =I37 -> 2572.853 | M36: =SUM($L36:L$39) -> 56314.49 | N36: =M37/M36 -> 0.95431277 | O36: 1-2 | R36: 0 | S36: 89326.78 | T36: 42183.22 | U36: 21462.92 | V36: 12638.42 | W36: 10342.97 | X36: 10335.73 | Y36: 9837.647 | AA36: 1 | AB36: =Y37 -> 8823.155 | AC36: =SUM($AB36:AB$39) -> 123800.42 | AD36: =AC37/AC36 -> 0.92873082 | AE36: 1-2
B37: 1 | C37: 6945.978 | D37: 11372.99 | E37: 7466.83 | F37: 4700.842 | G37: 3470.537 | H37: 2360.619 | I37: 2572.853 | K37: 2 | L37: =I38 -> 4720.019 | M37: =SUM($L37:L$39) -> 53741.637 | N37: =M38/M37 -> 0.91217203 | O37: 2-3 | R37: 1 | S37: 16818.97 | T37: 35587.46 | U37: 29689.8 | V37: 17736.86 | W37: 11974.25 | X37: 10259.28 | Y37: 8823.155 | AA37: 2 | AB37: =Y38 -> 23870.14 | AC37: =SUM($AB37:AB$39) -> 114977.27 | AD37: =AC38/AC37 -> 0.79239253 | AE37: 2-3
B38: 2 | C38: 2897.993 | D38: 10404.76 | E38: 11423.87 | F38: 10115.85 | G38: 8173.859 | H38: 6181.181 | I38: 4720.019 | K38: 3 | L38: =I39 -> 5507.268 | M38: =SUM($L38:L$39) -> 49021.618 | N38: =M39/M38 -> 0.88765634 | O38: 4+ | R38: 2 | S38: 4031.813 | T38: 22842.27 | U38: 33551.74 | V38: 35444.87 | W38: 31074.03 | X38: 27316.27 | Y38: 23870.14 | AA38: 3 | AB38: =Y39 -> 25913.43 | AC38: =SUM($AB38:AB$39) -> 91107.13 | AD38: =AC39/AC38 -> 0.71557188 | AE38: 4+
B39: 3 | C39: 714.6137 | D39: 6623.347 | E39: 10095.96 | F39: 10776.26 | G39: 9977.181 | H39: 7348.72 | I39: 5507.268 | K39: 4+ | L39: =I40 -> 43514.35 | M39: =SUM($L39:L$39) -> 43514.35 | N39: - | R39: 3 | S39: 829.2302 | T39: 10012.72 | U39: 22454.3 | V39: 28766.3 | W39: 28862.65 | X39: 27438.05 | Y39: 25913.43 | AA39: 4+ | AB39: =Y40 -> 65193.7 | AC39: =SUM($AB39:AB$39) -> 65193.7 | AD39: -
B40: 4+ | C40: 285.4511 | D40: 5090.159 | E40: 14999.22 | F40: 27560.66 | G40: 37176.12 | H40: 40410.64 | I40: 43514.35 | R40: 4+ | S40: 128.9239 | T40: 5155.988 | U40: 20015.34 | V40: 34514.56 | W40: 43017.09 | X40: 55041.99 | Y40: 65193.7
A42: , | B42: , | C42: ocupacao_v3 | D42: = | E42: sem_remuneracao | Q42: , | R42: , | S42: ocupacao_v3 | T42: = | U42: sem_remuneracao
K43: =E42 -> sem_remuneracao | AA43: =U42 -> sem_remuneracao
B44: idade_categ | K44: filhos_ever_born | L44: Número de mulheres de 45-49 anos | M44: Mulheres de 45-49 anos com pelo menos N filhos | N44: Razão de Perturição | O44: categ | R44: idade_categ | AA44: filhos_ever_born | AB44: Número de mulheres de 45-49 anos | AC44: Mulheres de 45-49 anos com pelo menos N filhos | AD44: Razão de Perturição | AE44: categ
...

Sheet descritiva_total
A1: ocupadas
A2: > | B2: svytable(~flag_ocup, | C2: design | D2: = | E2: mulheres_2000_aux)
A3: flag_ocup
B4: Desocupadas | C4: Ocupadas | D4: total
B5: 25636792 | C5: 21326033 | D5: =SUM(B5:C5) -> 46962825
B6: =B5/$D$5 -> 0.54589544 | C6: =C5/$D$5 -> 0.45410456 | D6: =D5/$D$5 -> 1
A9: > | B9: svytable(~flag_ocup, | C9: design | D9: =
A10: flag_ocup
B11: Desocupadas | C11: Ocupadas | D11: total
B12: 24075689 | C12: 29588816 | D12: =SUM(B12:C12) -> 53664505
B13: =B12/$D$12 -> 0.44863339 | C13: =C12/$D$12 -> 0.55136661 | D13: =D12/$D$12 -> 1
C15: 2000 | D15: 2010
B16: ocupadas | C16: =C6 -> 0.45410456 | D16: =C13 -> 0.55136661
B17: não ocupadas | C17: =B6 -> 0.54589544 | D17: =B13 -> 0.44863339
A22: mulheres por setor
A24: > | B24: data.frame(svytable(~ocupacao_v2, | C24: design | D24: = | E24: mulheres_2000_aux)) | G24: > | H24: svytable(~ocupacao_v2, | I24: design | J24: = | K24: mulheres_2000_aux)
B25: ocupacao_v2 | C25: Freq | D25: 2000 | G25: ocupacao_v2 | I25: 2010
A26: 1 | B26: conta_propria | C26: 4512360.4 | D26: =C26/SUM($C$26:$C$33) -> 0.15250223 | G26: conta_propria | H26: 3184432.6 | I26: =H26/SUM($H$26:$H$33) -> 0.14932137
A27: 2 | B27: empregadores | C27: 404911.45 | D27: =C27/SUM($C$26:$C$33) -> 0.013684611 | G27: empregadores | H27: 395220.64 | I27: =H27/SUM($H$26:$H$33) -> 0.018532309
A28: 3 | B28: emprego_com_carteira | C28: 14204783 | D28: =C28/SUM($C$26:$C$33) -> 0.48007269 | G28: emprego_com_carteira | H28: 8484492.1 | I28: =H28/SUM($H$26:$H$33) -> 0.3978467
A29: 4 | B29: emprego_sem_carteira | C29: 7053128.7 | D29: =C29/SUM($C$26:$C$33) -> 0.23837144 | G29: emprego_sem_carteira | H29: 6192401.6 | I29: =H29/SUM($H$26:$H$33) -> 0.29036819
A30: 5 | B30: funcionario_publico | C30: 1942434.2 | D30: =C30/SUM($C$26:$C$33) -> 0.065647582 | G30: funcionario_publico | H30: 1669697.9 | I30: =H30/SUM($H$26:$H$33) -> 0.078293881
A31: 6 | B31: militar | C31: 27670.06 | D31: =C31/SUM($C$26:$C$33) -> 0.00093515266 | G31: militar | H31: 18879.79 | I31: =H31/SUM($H$26:$H$33) -> 0.00088529309
A32: 7 | B32: proprio_consumo | C32: 872492.87 | D32: =C32/SUM($C$26:$C$33) -> 0.029487252 | G32: proprio_consumo | H32: 388807.33 | I32: =H32/SUM($H$26:$H$33) -> 0.018231582
A33: 8 | B33: sem_remuneracao | C33: 571035.59 | D33: =C33/SUM($C$26:$C$33) -> 0.019299035 | G33: sem_remuneracao | H33: 992101.39 | I33: =H33/SUM($H$26:$H$33) -> 0.046520671

Sheet Planilha1
A1: > | B1: data.frame(svytable(~idade_categ | C1: , | D1: design | E1: = | F1: mulheres_func_pub_aux))
B2: idade_categ | C2: Freq
A3: 1 | B3: 15-19 | C3: 45962.71
A4: 2 | B4: 20-24 | C4: 168925.72
A5: 3 | B5: 25-29 | C5: 241724.43
A6: 4 | B6: 30-34 | C6: 307254.86
A7: 5 | B7: 35-39 | C7: 342431.08
A8: 6 | B8: 40-44 | C8: 313926.99
A9: 7 | B9: 45-49 | C9: 249472.13
A10: > | B10: svytable(~idade_categ+V4620 | C10: , | D10: design | E10: = | F10: mulheres_1filho_aux)
B11: V4620
A12: idade_categ | B12: 1 | D12: TEF | E12: ponto_medio | F12: idade media
B13: 15-19 | C13: 3898.118 | D13: =C13/C3 -> 0.084810447 | E13: 17.5 | F13: =E13*D13 -> 1.4841828
B14: 20-24 | C14: 37640.275 | D14: =C14/C4 -> 0.22282146 | E14: 22.5 | F14: =E14*D14 -> 5.0134828
B15: 25-29 | C15: 65793.539 | D15: =C15/C5 -> 0.27218407 | E15: 27.5 | F15: =E15*D15 -> 7.4850619
B16: 30-34 | C16: 76978.841 | D16: =C16/C6 -> 0.25053742 | E16: 32.5 | F16: =E16*D16 -> 8.1424663
B17: 35-39 | C17: 66682.116 | D17: =C17/C7 -> 0.19473149 | E17: 37.5 | F17: =E17*D17 -> 7.302431
B18: 40-44 | C18: 49192.592 | D18: =C18/C8 -> 0.15670074 | E18: 42.5 | F18: =E18*D18 -> 6.6597815
B19: 45-49 | C19: 32058.06 | D19: =C19/C9 -> 0.12850357 | E19: 47.5 | F19: =E19*D19 -> 6.1039197
F20: =SUM(F13:F19)/SUM(D13:D19) -> 32.20001
A22: Conferindo
A23: === | B23: UF: | C23: 1101 | D23: - | E23: idade | F23: média | G23: da | H23: fecundidade | I23: de | J23: período | K23: ===
B24: idade_categ | C24: n_1filho | D24: total_mulheres | E24: TEF | F24: ponto_medio
A25: 1 | B25: 15-19 | C25: 0 | D25: 83.55225 | E25: 0 | F25: 17.5
A26: 2 | B26: 20-24 | C26: 110.45183 | D26: 413.70225 | E26: 0.26698389 | F26: 22.5
A27: 3 | B27: 25-29 | C27: 284.69543 | D27: 809.20592 | E27: 0.35182075 | F27: 27.5
A28: 4 | B28: 30-34 | C28: 335.84919 | D28: 1244.3892 | E28: 0.2698908 | F28: 32.5
A29: 5 | B29: 35-39 | C29: 258.61156 | D29: 1331.6934 | E29: 0.19419752 | F29: 37.5
A30: 6 | B30: 40-44 | C30: 131.16928 | D30: 1212.6042 | E30: 0.10817156 | F30: 42.5
A31: 7 | B31: 45-49 | C31: 57.03792 | D31: 700.79642 | E31: 0.08139015 | F31: 47.5
A32: Idade | B32: média | C32: da | D32: fecundidade | E32: de | F32: período | G32: (UF | H32: 1101 | I32: ): | J32: 31.6
B36: V4620
A37: idade_categ | C37: 1
B38: 15-19 | C38: 0
B39: 20-24 | C39: 110.45183
B40: 25-29 | C40: 284.69543
B41: 30-34 | C41: 335.84919
B42: 35-39 | C42: 258.61156
B43: 40-44 | C43: 131.16928
B44: 45-49 | C44: 57.037925
...

Sheet childless
A1: childless - proporcao de mulheres sem filhos - funcionarias publicas
A2: > | B2: data.frame(svytable(~idade_categ | C2: , | D2: design | E2: = | F2: mulheres_0filho_aux)) | J2: > | K2: data.frame(svytable(~idade_categ | L2: , | M2: design | N2: = | O2: mulheres_0filho_aux))
B3: idade_categ | C3: Freq | D3: total mulheres | E3: % | K3: idade_categ | L3: Freq | M3: total mulheres | N3: %
A4: 1 | B4: 15-19 | C4: 41345.27 | D4: 45962.714 | E4: =C4/D4 -> 0.89953936 | J4: 1 | K4: 15-19 | L4: 11624.63 | M4: 12730.08 | N4: =L4/M4 -> 0.91316237 | R4: mulheres com zero filhos
A5: 2 | B5: 20-24 | C5: 114488.49 | D5: 168925.72 | E5: =C5/D5 -> 0.67774456 | J5: 2 | K5: 20-24 | L5: 91917.41 | M5: 120566.8 | N5: =L5/M5 -> 0.76237745 | S5: func pub | T5: ocupadas
A6: 3 | B6: 25-29 | C6: 112067.06 | D6: 241724.43 | E6: =C6/D6 -> 0.46361494 | J6: 3 | K6: 25-29 | L6: 155555.3 | M6: 274550.33 | N6: =L6/M6 -> 0.56658209 | R6: 2000 | S6: =E12 -> 0.15214711 | T6: =D117 -> 0.11717421
A7: 4 | B7: 30-34 | C7: 83577.63 | D7: 307254.86 | E7: =C7/D7 -> 0.27201402 | J7: 4 | K7: 30-34 | L7: 120959.06 | M7: 358228.68 | N7: =L7/M7 -> 0.33765878 | R7: 2010 | S7: =N12 -> 0.16598492 | T7: =G117 -> 0.13271172
A8: 5 | B8: 35-39 | C8: 63920.48 | D8: 342431.08 | E8: =C8/D8 -> 0.1866667 | J8: 5 | K8: 35-39 | L8: 79087.21 | M8: 371043.8 | N8: =L8/M8 -> 0.21314791
A9: 6 | B9: 40-44 | C9: 47758.98 | D9: 313926.99 | E9: =C9/D9 -> 0.15213404 | J9: 6 | K9: 40-44 | L9: 69620.96 | M9: 400119.16 | N9: =L9/M9 -> 0.17400057
A10: 7 | B10: 45-49 | C10: 37960.57 | D10: 249472.13 | E10: =C10/D10 -> 0.15216357 | J10: 7 | K10: 45-49 | L10: 64049.11 | M10: 405195.37 | N10: =L10/M10 -> 0.1580697
C11: =SUM(C4:C10) -> 501118.48 | D11: =SUM(D4:D10) -> 1669697.9 | E11: =C11/D11 -> 0.30012523 | L11: =SUM(L4:L10) -> 592813.68 | M11: =SUM(M4:M10) -> 1942434.2 | N11: =L11/M11 -> 0.30519112
B12: 40-49 | C12: =SUM(C9:C10) -> 85719.55 | D12: =SUM(D9:D10) -> 563399.12 | E12: =C12/D12 -> 0.15214711 | K12: 40-49 | L12: =SUM(L9:L10) -> 133670.07 | M12: =SUM(M9:M10) -> 805314.53 | N12: =L12/M12 -> 0.16598492
A14: childless - por area de atuacao
A16: > | B16: svytable(~idade_categ+sub_grupo_cnae | C16: , | D16: design | E16: = | F16: mulheres_0filho_aux) | J16: > | K16: svytable(~idade_categ+sub_grupo_cnae | L16: , | M16: design | N16: = | O16: mulheres_0filho_aux)
B17: sub_grupo_cnae | K17: sub_grupo_cnae
A18: idade_categ | C18: adm_e_gestao_publica | D18: educacao | E18: outras | F18: saude | G18: total | J18: idade_categ | L18: adm_e_gestao_publica | M18: educacao | N18: outras | O18: saude | P18: total
B19: 15-19 | C19: 14009.261 | D19: 15549.304 | E19: 9001.739 | F19: 2784.969 | G19: =SUM(C19:F19) -> 41345.273 | K19: 15-19 | L19: 5964.061 | M19: 3690.0861 | N19: 833.9439 | O19: 1136.5365 | P19: =SUM(L19:O19) -> 11624.628
B20: 20-24 | C20: 33346.162 | D20: 62917.077 | E20: 10297.609 | F20: 7927.644 | G20: =SUM(C20:F20) -> 114488.49 | K20: 20-24 | L20: 40658.528 | M20: 32774.224 | N20: 4642.3708 | O20: 13842.288 | P20: =SUM(L20:O20) -> 91917.411
B21: 25-29 | C21: 34009.397 | D21: 61669.095 | E21: 6415.917 | F21: 9972.653 | G21: =SUM(C21:F21) -> 112067.06 | K21: 25-29 | L21: 64329.495 | M21: 57730.918 | N21: 8004.1216 | O21: 25490.767 | P21: =SUM(L21:O21) -> 155555.3
B22: 30-34 | C22: 26200.658 | D22: 45701.849 | E22: 4206.282 | F22: 7468.847 | G22: =SUM(C22:F22) -> 83577.636 | K22: 30-34 | L22: 47985.174 | M22: 50612.12 | N22: 5319.4125 | O22: 17042.353 | P22: =SUM(L22:O22) -> 120959.06
B23: 35-39 | C23: 21385.228 | D23: 33734.346 | E23: 3177.039 | F23: 5623.863 | G23: =SUM(C23:F23) -> 63920.476 | K23: 35-39 | L23: 28837.416 | M23: 36989.546 | N23: 3376.0968 | O23: 9884.1523 | P23: =SUM(L23:O23) -> 79087.211
B24: 40-44 | C24: 15566.82 | D24: 24605.822 | E24: 2665.17 | F24: 4921.167 | G24: =SUM(C24:F24) -> 47758.979 | K24: 40-44 | L24: 24592.974 | M24: 33925.788 | N24: 2395.5558 | O24: 8706.6408 | P24: =SUM(L24:O24) -> 69620.959
B25: 45-49 | C25: 11861.199 | D25: 20355.189 | E25: 1972.151 | F25: 3772.027 | G25: =SUM(C25:F25) -> 37960.566 | K25: 45-49 | L25: 23513.085 | M25: 31300.877 | N25: 2355.2549 | O25: 6879.8948 | P25: =SUM(L25:O25) -> 64049.111
B26: total | C26: =SUM(C19:C25) -> 156378.72 | D26: =SUM(D19:D25) -> 264532.68 | E26: =SUM(E19:E25) -> 37735.907 | F26: =SUM(F19:F25) -> 42471.17 | G26: =SUM(C26:F26) -> 501118.48 | K26: total | L26: =SUM(L19:L25) -> 235880.73 | M26: =SUM(M19:M25) -> 247023.56 | N26: =SUM(N19:N25) -> 26926.756 | O26: =SUM(O19:O25) -> 82982.632 | P26: =SUM(L26:O26) -> 592813.68
A28: > | B28: svytable(~idade_categ+sub_grupo_cnae,design | C28: = | D28: mulheres_func_pub_aux)#total | E28: de | F28: mulheres | G28: por | H28: grupo | I28: cnae | J28: > | K28: svytable(~idade_categ+sub_grupo_cnae,design | L28: = | M28: mulheres_func_pub_aux)#total | N28: de | O28: mulheres | P28: por | Q28: grupo | R28: cnae
B29: sub_grupo_cnae | K29: sub_grupo_cnae
A30: idade_categ | C30: adm_e_gestao_publica | D30: educacao | E30: outras | F30: saude | G30: total | J30: idade_categ | L30: adm_e_gestao_publica | M30: educacao | N30: outras | O30: saude | P30: total
B31: 15-19 | C31: 15503.61 | D31: 17333.87 | E31: 10099.36 | F31: 3025.88 | G31: =SUM(C31:F31) -> 45962.72 | K31: 15-19 | L31: 6530.2336 | M31: 4072.5238 | N31: 873.0236 | O31: 1254.2995 | P31: =SUM(L31:O31) -> 12730.081
B32: 20-24 | C32: 49903.19 | D32: 91467.21 | E32: 15652.61 | F32: 11902.72 | G32: =SUM(C32:F32) -> 168925.73 | K32: 20-24 | L32: 52835.538 | M32: 43930.978 | N32: 5627.5604 | O32: 18172.722 | P32: =SUM(L32:O32) -> 120566.8
B33: 25-29 | C33: 72723.56 | D33: 133881.38 | E33: 14921.33 | F33: 20198.17 | G33: =SUM(C33:F33) -> 241724.44 | K33: 25-29 | L33: 109576.08 | M33: 109988.29 | N33: 11481.472 | O33: 43504.488 | P33: =SUM(L33:O33) -> 274550.33
B34: 30-34 | C34: 92983.7 | D34: 168356.79 | E34: 17436.29 | F34: 28478.08 | G34: =SUM(C34:F34) -> 307254.86 | K34: 30-34 | L34: 132276.64 | M34: 163435.79 | N34: 11581.098 | O34: 50935.161 | P34: =SUM(L34:O34) -> 358228.68
B35: 35-39 | C35: 108539.86 | D35: 181423.15 | E35: 19238.31 | F35: 33229.75 | G35: =SUM(C35:F35) -> 342431.07 | K35: 35-39 | L35: 132336.94 | M35: 179842.01 | N35: 11012.288 | O35: 47852.557 | P35: =SUM(L35:O35) -> 371043.8
B36: 40-44 | C36: 97889.13 | D36: 164823.15 | E36: 18005.37 | F36: 33209.34 | G36: =SUM(C36:F36) -> 313926.99 | K36: 40-44 | L36: 142696.5 | M36: 197418.91 | N36: 11615.487 | O36: 48388.262 | P36: =SUM(L36:O36) -> 400119.17
B37: 45-49 | C37: 71493.05 | D37: 138796.67 | E37: 14100.14 | F37: 25082.28 | G37: =SUM(C37:F37) -> 249472.14 | K37: 45-49 | L37: 146847.8 | M37: 197686.11 | N37: 12599.629 | O37: 48061.835 | P37: =SUM(L37:O37) -> 405195.37
B38: total | C38: =SUM(C31:C37) -> 509036.1 | D38: =SUM(D31:D37) -> 896082.22 | E38: =SUM(E31:E37) -> 109453.41 | F38: =SUM(F31:F37) -> 155126.22 | G38: =SUM(C38:F38) -> 1669697.9 | K38: total | L38: =SUM(L31:L37) -> 723099.73 | M38: =SUM(M31:M37) -> 896374.61 | N38: =SUM(N31:N37) -> 64790.559 | O38: =SUM(O31:O37) -> 258169.33 | P38: =SUM(L38:O38) -> 1942434.2
C41: administrcao | D41: educacao | E41: outras | F41: saude | G41: total | L41: adm_e_gestao_publica | M41: educacao | N41: outras | O41: saude | P41: total
B42: =B31 -> 15-19 | C42: =C19/C31 -> 0.90361284 | D42: =D19/D31 -> 0.89704746 | E42: =E19/E31 -> 0.89131777 | F42: =F19/F31 -> 0.92038316 | G42: =G19/G31 -> 0.8995393 | K42: =K31 -> 15-19 | L42: =L19/L31 -> 0.91329979 | M42: =M19/M31 -> 0.90609319 | N42: =N19/N31 -> 0.95523638 | O42: =O19/O31 -> 0.90611254 | P42: =P19/P31 -> 0.91316214
B43: =B32 -> 20-24 | C43: =C20/C32 -> 0.66821704 | D43: =D20/D32 -> 0.68786483 | E43: =E20/E32 -> 0.65788447 | F43: =F20/F32 -> 0.66603633 | G43: =G20/G32 -> 0.67774454 | K43: =K32 -> 20-24 | L43: =L20/L32 -> 0.76952993 | M43: =M20/M32 -> 0.74603902 | N43: =N20/N32 -> 0.82493487 | O43: =O20/O32 -> 0.7617069 | P43: =P20/P32 -> 0.76237747
B44: =B33 -> 25-29 | C44: =C21/C33 -> 0.46765308 | D44: =D21/D33 -> 0.46062488 | E44: =E21/E33 -> 0.42998292 | F44: =F21/F33 -> 0.49374042 | G44: =G21/G33 -> 0.46361494 | K44: =K33 -> 25-29 | L44: =L21/L33 -> 0.58707608 | M44: =M21/M33 -> 0.52488239 | N44: =N21/N33 -> 0.69713373 | O44: =O21/O33 -> 0.58593418 | P44: =P21/P33 -> 0.56658209
B45: =B34 -> 30-34 | C45: =C22/C34 -> 0.28177689 | D45: =D22/D34 -> 0.27145831 | E45: =E22/E34 -> 0.24123721 | F45: =F22/F34 -> 0.26226652 | G45: =G22/G34 -> 0.27201404 | K45: =K34 -> 30-34 | L45: =L22/L34 -> 0.36276379 | M45: =M22/M34 -> 0.30967587 | N45: =N22/N34 -> 0.45931849 | O45: =O22/O34 -> 0.33458915 | P45: =P22/P34 -> 0.33765878
...

Sheet idade_media_primeiro_filho
A1: idade media ao primeiro filho
A2: > | B2: data.frame(svytable(~idade_categ | C2: , | D2: design | E2: = | F2: mulheres_1filho_aux)) | J2: > | K2: data.frame(svytable(~idade_categ | L2: , | M2: design | N2: = | O2: mulheres_1filho_aux))
B3: idade_categ | C3: Freq | D3: total mulheres | E3: TEF | F3: ponto_medio | K3: idade_categ | L3: Freq | M3: total mulheres | N3: TEF | O3: ponto_medio
A4: 1 | B4: 15-19 | C4: 3898.118 | D4: 45962.714 | E4: =C4/D4 -> 0.08481044 | F4: 17.5 | G4: =F4*E4 -> 1.4841827 | J4: 1 | K4: 15-19 | L4: 972.507 | M4: 12730.08 | N4: =L4/M4 -> 0.076394414 | O4: 17.5 | P4: =O4*N4 -> 1.3369022
A5: 2 | B5: 20-24 | C5: 37640.275 | D5: 168925.72 | E5: =C5/D5 -> 0.22282145 | F5: 22.5 | G5: =F5*E5 -> 5.0134827 | J5: 2 | K5: 20-24 | L5: 21823.172 | M5: 120566.8 | N5: =L5/M5 -> 0.18100482 | O5: 22.5 | P5: =O5*N5 -> 4.0726085
A6: 3 | B6: 25-29 | C6: 65793.539 | D6: 241724.43 | E6: =C6/D6 -> 0.27218406 | F6: 27.5 | G6: =F6*E6 -> 7.4850618 | J6: 3 | K6: 25-29 | L6: 74569.968 | M6: 274550.33 | N6: =L6/M6 -> 0.27160764 | O6: 27.5 | P6: =O6*N6 -> 7.4692102
A7: 4 | B7: 30-34 | C7: 76978.841 | D7: 307254.86 | E7: =C7/D7 -> 0.25053742 | F7: 32.5 | G7: =F7*E7 -> 8.1424662 | J7: 4 | K7: 30-34 | L7: 113349.43 | M7: 358228.68 | N7: =L7/M7 -> 0.31641639 | O7: 32.5 | P7: =O7*N7 -> 10.283533
A8: 5 | B8: 35-39 | C8: 66682.116 | D8: 342431.08 | E8: =C8/D8 -> 0.1947315 | F8: 37.5 | G8: =F8*E8 -> 7.3024312 | J8: 5 | K8: 35-39 | L8: 100246.98 | M8: 371043.8 | N8: =L8/M8 -> 0.2701756 | O8: 37.5 | P8: =O8*N8 -> 10.131585
A9: 6 | B9: 40-44 | C9: 49192.592 | D9: 313926.99 | E9: =C9/D9 -> 0.15670074 | F9: 42.5 | G9: =F9*E9 -> 6.6597815 | J9: 6 | K9: 40-44 | L9: 87833.318 | M9: 400119.16 | N9: =L9/M9 -> 0.2195179 | O9: 42.5 | P9: =O9*N9 -> 9.3295108
A10: 7 | B10: 45-49 | C10: 32058.06 | D10: 249472.13 | E10: =C10/D10 -> 0.12850357 | F10: 47.5 | G10: =F10*E10 -> 6.1039198 | J10: 7 | K10: 45-49 | L10: 75909.169 | M10: 405195.37 | N10: =L10/M10 -> 0.18733968 | O10: 47.5 | P10: =O10*N10 -> 8.8986346
G11: =SUM(G4:G10)/SUM(E4:E10) -> 32.200011 | P11: =SUM(P4:P10)/SUM(N4:N10) -> 33.841352
A13: Por áre a de atuacao
A15: > | B15: svytable(~idade_categ+sub_grupo_cnae | C15: , | D15: design | E15: = | F15: mulheres_1filho_aux) | J15: > | K15: svytable(~idade_categ+sub_grupo_cnae | L15: , | M15: design | N15: = | O15: mulheres_1filho_aux)
B16: sub_grupo_cnae | K16: sub_grupo_cnae
A17: idade_categ | C17: adm_e_gestao_publica | D17: educacao | E17: outras | F17: saude | J17: idade_categ | K17: adm_e_gestao_publica | L17: educacao | M17: outras | N17: saude
B18: 15-19 | C18: 1241.2717 | D18: 1604.0766 | E18: 856.5474 | F18: 196.2221 | K18: 15-19 | L18: 494.85517 | M18: 329.94025 | N18: 39.07973 | O18: 108.63188
B19: 20-24 | C19: 11027.547 | D19: 20425.599 | E19: 3436.6341 | F19: 2750.4953 | K19: 20-24 | L19: 9247.817 | M19: 8341.751 | N19: 651.61429 | O19: 3581.9895
B20: 25-29 | C20: 19037.078 | D20: 37850.188 | E20: 3587.7814 | F20: 5318.4913 | K20: 25-29 | L20: 28121.904 | M20: 32493.514 | N20: 2144.4463 | O20: 11810.104
B21: 30-34 | C21: 23146.302 | D21: 43284.284 | E21: 3535.1149 | F21: 7013.1401 | K21: 30-34 | L21: 40529.422 | M21: 53161.831 | N21: 3236.217 | O21: 16421.956
B22: 35-39 | C22: 21294.742 | D22: 34634.016 | E22: 3454.368 | F22: 7298.9896 | K22: 35-39 | L22: 36010.362 | M22: 48691.951 | N22: 2662.0835 | O22: 12882.586
B23: 40-44 | C23: 16579.628 | D23: 24339.334 | E23: 2584.2938 | F23: 5689.337 | K23: 40-44 | L23: 31949.806 | M23: 42759.672 | N23: 2405.269 | O23: 10718.571
B24: 45-49 | C24: 10331.06 | D24: 16592.802 | E24: 1688.9735 | F24: 3445.2239 | K24: 45-49 | L24: 29067.78 | M24: 35424.918 | N24: 2678.5346 | O24: 8737.9362
A26: > | B26: svytable(~idade_categ+sub_grupo_cnae,design | C26: = | D26: mulheres_func_pub_aux)#total | E26: de | F26: mulheres | G26: por | H26: grupo | I26: cnae | J26: > | K26: svytable(~idade_categ+sub_grupo_cnae,design | L26: = | M26: mulheres_func_pub_aux)#total | N26: de | O26: mulheres | P26: por | Q26: grupo | R26: cnae
B27: sub_grupo_cnae | K27: sub_grupo_cnae
A28: idade_categ | C28: adm_e_gestao_publica | D28: educacao | E28: outras | F28: saude | J28: idade_categ | K28: adm_e_gestao_publica | L28: educacao | M28: outras | N28: saude
B29: 15-19 | C29: 15503.61 | D29: 17333.87 | E29: 10099.36 | F29: 3025.88 | K29: 15-19 | L29: 6530.2336 | M29: 4072.5238 | N29: 873.0236 | O29: 1254.2995
B30: 20-24 | C30: 49903.19 | D30: 91467.21 | E30: 15652.61 | F30: 11902.72 | K30: 20-24 | L30: 52835.538 | M30: 43930.978 | N30: 5627.5604 | O30: 18172.722
B31: 25-29 | C31: 72723.56 | D31: 133881.38 | E31: 14921.33 | F31: 20198.17 | K31: 25-29 | L31: 109576.08 | M31: 109988.29 | N31: 11481.472 | O31: 43504.488
B32: 30-34 | C32: 92983.7 | D32: 168356.79 | E32: 17436.29 | F32: 28478.08 | K32: 30-34 | L32: 132276.64 | M32: 163435.79 | N32: 11581.098 | O32: 50935.161
B33: 35-39 | C33: 108539.86 | D33: 181423.15 | E33: 19238.31 | F33: 33229.75 | K33: 35-39 | L33: 132336.94 | M33: 179842.01 | N33: 11012.288 | O33: 47852.557
B34: 40-44 | C34: 97889.13 | D34: 164823.15 | E34: 18005.37 | F34: 33209.34 | K34: 40-44 | L34: 142696.5 | M34: 197418.91 | N34: 11615.487 | O34: 48388.262
B35: 45-49 | C35: 71493.05 | D35: 138796.67 | E35: 14100.14 | F35: 25082.28 | K35: 45-49 | L35: 146847.8 | M35: 197686.11 | N35: 12599.629 | O35: 48061.835
B37: ponto_medio | C37: adm_e_gestao_publica | D37: educacao | E37: outras | F37: saude | K37: ponto_medio | L37: adm_e_gestao_publica | M37: educacao | N37: outras | O37: saude
B38: 17.5 | C38: =C18/C29 -> 0.080063398 | D38: =D18/D29 -> 0.092540016 | E38: =E18/E29 -> 0.084812047 | F38: =F18/F29 -> 0.064847945 | K38: 17.5 | L38: =L18/L29 -> 0.075779092 | M38: =M18/M29 -> 0.081016163 | N38: =N18/N29 -> 0.044763658 | O38: =O18/O29 -> 0.086607608
