Workbook

Sheet parity
A1: total
A2: ACHIVED | Y2: DESIRED
B3: Women by age group and parity | Z3: Women by age group and parity
A4: Parity (i) | B4: 15-19 | C4: 20-24 | D4: 25-29 | E4: 30-34 | F4: 35-39 | G4: 40-44 | H4: 45-49 | I4: 40-49 | L4: Unprojected proportions of women with at least i children | Y4: Parity (i) | Z4: 15-19 | AA4: 20-24 | AB4: 25-29 | AC4: 30-34 | AD4: 35-39 | AE4: 40-44 | AF4: 45-49 | AG4: 40-49 | AJ4: Unprojected proportions of women with at least i children
A5: 0 | B5: 0 | C5: 47283.103 | D5: 54227.258 | E5: 62636.767 | F5: 74948.84 | G5: 72814.219 | H5: 118978.65 | I5: =SUM(G5:H5) -> 191792.87 | K5: Parity (i) | L5: 15-19 | M5: 20-24 | N5: 25-29 | O5: 30-34 | P5: 35-39 | Q5: 40-44 | R5: 45-49 | S5: 40-49 | Y5: 0 | Z5: 0 | AA5: 47283.103 | AB5: 54227.258 | AC5: 62636.767 | AD5: 74948.84 | AE5: 72814.219 | AF5: 118978.65 | AG5: =SUM(AE5:AF5) -> 191792.87 | AI5: Parity (i) | AJ5: 15-19 | AK5: 20-24 | AL5: 25-29 | AM5: 30-34 | AN5: 35-39 | AO5: 40-44 | AP5: 45-49 | AQ5: 40-49
A6: 1 | B6: 8337.5554 | C6: 24635.409 | D6: 29869.735 | E6: 77758.539 | F6: 81532.505 | G6: 44045.462 | H6: 87226.992 | I6: =SUM(G6:H6) -> 131272.45 | K6: =A5 -> 0 | L6: =SUM(B5:B$23)/B$24 -> 1 | M6: =SUM(C5:C$23)/C$24 -> 1 | N6: =SUM(D5:D$23)/D$24 -> 1 | O6: =SUM(E5:E$23)/E$24 -> 1 | P6: =SUM(F5:F$23)/F$24 -> 1 | Q6: =SUM(G5:G$23)/G$24 -> 1 | R6: =SUM(H5:H$23)/H$24 -> 1 | S6: =SUM(I5:I$23)/I$24 -> 1 | Y6: 1 | Z6: 8337.5554 | AA6: 24635.409 | AB6: 29869.735 | AC6: 77758.539 | AD6: 81532.505 | AE6: 44045.462 | AF6: 87226.992 | AG6: =SUM(AE6:AF6) -> 131272.45 | AI6: =Y5 -> 0 | AJ6: =SUM(Z5:Z$23)/Z$24 -> 1 | AK6: =SUM(AA5:AA$23)/AA$24 -> 1 | AL6: =SUM(AB5:AB$23)/AB$24 -> 1 | AM6: =SUM(AC5:AC$23)/AC$24 -> 1 | AN6: =SUM(AD5:AD$23)/AD$24 -> 1 | AO6: =SUM(AE5:AE$23)/AE$24 -> 1 | AP6: =SUM(AF5:AF$23)/AF$24 -> 1 | AQ6: =SUM(AG5:AG$23)/AG$24 -> 1
A7: 2 | B7: 0 | C7: 6770.633 | D7: 36573.017 | E7: 54308.839 | F7: 54748.566 | G7: 167541.15 | H7: 75359.979 | I7: =SUM(G7:H7) -> 242901.13 | K7: =A6 -> 1 | L7: =SUM(B6:B$23)/B$24 -> 1 | M7: =SUM(C6:C$23)/C$24 -> 0.3991153 | N7: =SUM(D6:D$23)/D$24 -> 0.59875777 | O7: =SUM(E6:E$23)/E$24 -> 0.69235394 | P7: =SUM(F6:F$23)/F$24 -> 0.69942003 | Q7: =SUM(G6:G$23)/G$24 -> 0.79410665 | R7: =SUM(H6:H$23)/H$24 -> 0.6522101 | S7: =SUM(I6:I$23)/I$24 -> 0.72433627 | Y7: 2 | Z7: 0 | AA7: 6770.633 | AB7: 36573.017 | AC7: 54308.839 | AD7: 54748.566 | AE7: 167541.15 | AF7: 75359.979 | AG7: =SUM(AE7:AF7) -> 242901.13 | AI7: =Y6 -> 1 | AJ7: =SUM(Z6:Z$23)/Z$24 -> 1 | AK7: =SUM(AA6:AA$23)/AA$24 -> 0.3991153 | AL7: =SUM(AB6:AB$23)/AB$24 -> 0.59875777 | AM7: =SUM(AC6:AC$23)/AC$24 -> 0.69235394 | AN7: =SUM(AD6:AD$23)/AD$24 -> 0.69942003 | AO7: =SUM(AE6:AE$23)/AE$24 -> 0.79410665 | AP7: =SUM(AF6:AF$23)/AF$24 -> 0.6522101 | AQ7: =SUM(AG6:AG$23)/AG$24 -> 0.72433627
A8: 3 | B8: 0 | C8: 0 | D8: 14478.422 | E8: 7068.6608 | F8: 29439.268 | G8: 52789.511 | H8: 32289.43 | I8: =SUM(G8:H8) -> 85078.94 | K8: =A7 -> 2 | L8: =SUM(B7:B$23)/B$24 -> 0 | M8: =SUM(C7:C$23)/C$24 -> 0.086042782 | N8: =SUM(D7:D$23)/D$24 -> 0.37774348 | O8: =SUM(E7:E$23)/E$24 -> 0.31043594 | P8: =SUM(F7:F$23)/F$24 -> 0.37243647 | Q8: =SUM(G7:G$23)/G$24 -> 0.66956137 | R8: =SUM(H7:H$23)/H$24 -> 0.39723438 | S8: =SUM(I7:I$23)/I$24 -> 0.53565849 | Y8: 3 | Z8: 0 | AA8: 0 | AB8: 14478.422 | AC8: 7068.6608 | AD8: 29439.268 | AE8: 52789.511 | AF8: 32289.43 | AG8: =SUM(AE8:AF8) -> 85078.94 | AI8: =Y7 -> 2 | AJ8: =SUM(Z7:Z$23)/Z$24 -> 0 | AK8: =SUM(AA7:AA$23)/AA$24 -> 0.086042782 | AL8: =SUM(AB7:AB$23)/AB$24 -> 0.37774348 | AM8: =SUM(AC7:AC$23)/AC$24 -> 0.31043594 | AN8: =SUM(AD7:AD$23)/AD$24 -> 0.37243647 | AO8: =SUM(AE7:AE$23)/AE$24 -> 0.66956137 | AP8: =SUM(AF7:AF$23)/AF$24 -> 0.39723438 | AQ8: =SUM(AG7:AG$23)/AG$24 -> 0.53565849
A9: 4 | B9: 0 | C9: 0 | D9: 0 | E9: 0 | F9: 8678.2383 | G9: 3452.3552 | H9: 6592.9918 | I9: =SUM(G9:H9) -> 10045.347 | K9: =A8 -> 3 | L9: =SUM(B8:B$23)/B$24 -> 0 | M9: =SUM(C8:C$23)/C$24 -> 0 | N9: =SUM(D8:D$23)/D$24 -> 0.10712978 | O9: =SUM(E8:E$23)/E$24 -> 0.043693236 | P9: =SUM(F8:F$23)/F$24 -> 0.15286906 | Q9: =SUM(G8:G$23)/G$24 -> 0.19581312 | R9: =SUM(H8:H$23)/H$24 -> 0.17694748 | S9: =SUM(I8:I$23)/I$24 -> 0.1865369 | Y9: 4 | Z9: 0 | AA9: 0 | AB9: 0 | AC9: 0 | AD9: 8678.2383 | AE9: 3452.3552 | AF9: 6592.9918 | AG9: =SUM(AE9:AF9) -> 10045.347 | AI9: =Y8 -> 3 | AJ9: =SUM(Z8:Z$23)/Z$24 -> 0 | AK9: =SUM(AA8:AA$23)/AA$24 -> 0 | AL9: =SUM(AB8:AB$23)/AB$24 -> 0.10712978 | AM9: =SUM(AC8:AC$23)/AC$24 -> 0.043693236 | AN9: =SUM(AD8:AD$23)/AD$24 -> 0.15286906 | AO9: =SUM(AE8:AE$23)/AE$24 -> 0.19581312 | AP9: =SUM(AF8:AF$23)/AF$24 -> 0.17694748 | AQ9: =SUM(AG8:AG$23)/AG$24 -> 0.1865369
A10: 5 | B10: 0 | C10: 0 | D10: 0 | E10: 1827.2861 | F10: 0 | G10: 3171.7864 | H10: 19261.645 | I10: =SUM(G10:H10) -> 22433.432 | K10: =A9 -> 4 | L10: =SUM(B9:B$23)/B$24 -> 0 | M10: =SUM(C9:C$23)/C$24 -> 0 | N10: =SUM(D9:D$23)/D$24 -> 0 | O10: =SUM(E9:E$23)/E$24 -> 0.0089748785 | P10: =SUM(F9:F$23)/F$24 -> 0.034803803 | Q10: =SUM(G9:G$23)/G$24 -> 0.046542694 | R10: =SUM(H9:H$23)/H$24 -> 0.082561321 | S10: =SUM(I9:I$23)/I$24 -> 0.064253014 | Y10: 5 | Z10: 0 | AA10: 0 | AB10: 0 | AC10: 1827.2861 | AD10: 0 | AE10: 3171.7864 | AF10: 19261.645 | AG10: =SUM(AE10:AF10) -> 22433.432 | AI10: =Y9 -> 4 | AJ10: =SUM(Z9:Z$23)/Z$24 -> 0 | AK10: =SUM(AA9:AA$23)/AA$24 -> 0 | AL10: =SUM(AB9:AB$23)/AB$24 -> 0 | AM10: =SUM(AC9:AC$23)/AC$24 -> 0.0089748785 | AN10: =SUM(AD9:AD$23)/AD$24 -> 0.034803803 | AO10: =SUM(AE9:AE$23)/AE$24 -> 0.046542694 | AP10: =SUM(AF9:AF$23)/AF$24 -> 0.082561321 | AQ10: =SUM(AG9:AG$23)/AG$24 -> 0.064253014
A11: 6 | B11: 0 | C11: 0 | D11: 0 | E11: 0 | F11: 0 | G11: 0 | H11: 2247.111 | I11: =SUM(G11:H11) -> 2247.111 | K11: =A10 -> 5 | L11: =SUM(B10:B$23)/B$24 -> 0 | M11: =SUM(C10:C$23)/C$24 -> 0 | N11: =SUM(D10:D$23)/D$24 -> 0 | O11: =SUM(E10:E$23)/E$24 -> 0.0089748785 | P11: =SUM(F10:F$23)/F$24 -> 0 | Q11: =SUM(G10:G$23)/G$24 -> 0.036780631 | R11: =SUM(H10:H$23)/H$24 -> 0.063289159 | S11: =SUM(I10:I$23)/I$24 -> 0.049814845 | Y11: 6 | Z11: 0 | AA11: 0 | AB11: 0 | AC11: 0 | AD11: 0 | AE11: 0 | AF11: 2247.111 | AG11: =SUM(AE11:AF11) -> 2247.111 | AI11: =Y10 -> 5 | AJ11: =SUM(Z10:Z$23)/Z$24 -> 0 | AK11: =SUM(AA10:AA$23)/AA$24 -> 0 | AL11: =SUM(AB10:AB$23)/AB$24 -> 0 | AM11: =SUM(AC10:AC$23)/AC$24 -> 0.0089748785 | AN11: =SUM(AD10:AD$23)/AD$24 -> 0 | AO11: =SUM(AE10:AE$23)/AE$24 -> 0.036780631 | AP11: =SUM(AF10:AF$23)/AF$24 -> 0.063289159 | AQ11: =SUM(AG10:AG$23)/AG$24 -> 0.049814845
A12: 8 | B12: 0 | C12: 0 | D12: 0 | E12: 0 | F12: 0 | G12: 812.5582 | H12: 0 | I12: =SUM(G12:H12) -> 812.5582 | K12: =A11 -> 6 | L12: =SUM(B11:B$23)/B$24 -> 0 | M12: =SUM(C11:C$23)/C$24 -> 0 | N12: =SUM(D11:D$23)/D$24 -> 0 | O12: =SUM(E11:E$23)/E$24 -> 0 | P12: =SUM(F11:F$23)/F$24 -> 0 | Q12: =SUM(G11:G$23)/G$24 -> 0.02781192 | R12: =SUM(H11:H$23)/H$24 -> 0.006984892 | S12: =SUM(I11:I$23)/I$24 -> 0.017571293 | Y12: 8 | Z12: 0 | AA12: 0 | AB12: 0 | AC12: 0 | AD12: 0 | AE12: 812.5582 | AF12: 0 | AG12: =SUM(AE12:AF12) -> 812.5582 | AI12: =Y11 -> 6 | AJ12: =SUM(Z11:Z$23)/Z$24 -> 0 | AK12: =SUM(AA11:AA$23)/AA$24 -> 0 | AL12: =SUM(AB11:AB$23)/AB$24 -> 0 | AM12: =SUM(AC11:AC$23)/AC$24 -> 0 | AN12: =SUM(AD11:AD$23)/AD$24 -> 0 | AO12: =SUM(AE11:AE$23)/AE$24 -> 0.02781192 | AP12: =SUM(AF11:AF$23)/AF$24 -> 0.006984892 | AQ12: =SUM(AG11:AG$23)/AG$24 -> 0.017571293
A13: 9 | B13: 0 | C13: 0 | D13: 0 | E13: 0 | F13: 0 | G13: 9023.1321 | H13: 0 | I13: =SUM(G13:H13) -> 9023.1321 | K13: =A12 -> 8 | L13: =SUM(B12:B$23)/B$24 -> 0 | M13: =SUM(C12:C$23)/C$24 -> 0 | N13: =SUM(D12:D$23)/D$24 -> 0 | O13: =SUM(E12:E$23)/E$24 -> 0 | P13: =SUM(F12:F$23)/F$24 -> 0 | Q13: =SUM(G12:G$23)/G$24 -> 0.02781192 | R13: =SUM(H12:H$23)/H$24 -> 0.00041629765 | S13: =SUM(I12:I$23)/I$24 -> 0.014341522 | Y13: 9 | Z13: 0 | AA13: 0 | AB13: 0 | AC13: 0 | AD13: 0 | AE13: 9023.1321 | AF13: 0 | AG13: =SUM(AE13:AF13) -> 9023.1321 | AI13: =Y12 -> 8 | AJ13: =SUM(Z12:Z$23)/Z$24 -> 0 | AK13: =SUM(AA12:AA$23)/AA$24 -> 0 | AL13: =SUM(AB12:AB$23)/AB$24 -> 0 | AM13: =SUM(AC12:AC$23)/AC$24 -> 0 | AN13: =SUM(AD12:AD$23)/AD$24 -> 0 | AO13: =SUM(AE12:AE$23)/AE$24 -> 0.02781192 | AP13: =SUM(AF12:AF$23)/AF$24 -> 0.00041629765 | AQ13: =SUM(AG12:AG$23)/AG$24 -> 0.014341522
A14: 12 | B14: 0 | C14: 0 | D14: 0 | E14: 0 | F14: 0 | G14: 0 | H14: 142.4151 | I14: =SUM(G14:H14) -> 142.4151 | K14: =A13 -> 9 | L14: =SUM(B13:B$23)/B$24 -> 0 | M14: =SUM(C13:C$23)/C$24 -> 0 | N14: =SUM(D13:D$23)/D$24 -> 0 | O14: =SUM(E13:E$23)/E$24 -> 0 | P14: =SUM(F13:F$23)/F$24 -> 0 | Q14: =SUM(G13:G$23)/G$24 -> 0.025514287 | R14: =SUM(H13:H$23)/H$24 -> 0.00041629765 | S14: =SUM(I13:I$23)/I$24 -> 0.013173633 | Y14: 12 | Z14: 0 | AA14: 0 | AB14: 0 | AC14: 0 | AD14: 0 | AE14: 0 | AF14: 142.4151 | AG14: =SUM(AE14:AF14) -> 142.4151 | AI14: =Y13 -> 9 | AJ14: =SUM(Z13:Z$23)/Z$24 -> 0 | AK14: =SUM(AA13:AA$23)/AA$24 -> 0 | AL14: =SUM(AB13:AB$23)/AB$24 -> 0 | AM14: =SUM(AC13:AC$23)/AC$24 -> 0 | AN14: =SUM(AD13:AD$23)/AD$24 -> 0 | AO14: =SUM(AE13:AE$23)/AE$24 -> 0.025514287 | AP14: =SUM(AF13:AF$23)/AF$24 -> 0.00041629765 | AQ14: =SUM(AG13:AG$23)/AG$24 -> 0.013173633
K15: =A14 -> 12 | L15: =SUM(B14:B$23)/B$24 -> 0 | M15: =SUM(C14:C$23)/C$24 -> 0 | N15: =SUM(D14:D$23)/D$24 -> 0 | O15: =SUM(E14:E$23)/E$24 -> 0 | P15: =SUM(F14:F$23)/F$24 -> 0 | Q15: =SUM(G14:G$23)/G$24 -> 0 | R15: =SUM(H14:H$23)/H$24 -> 0.00041629765 | S15: =SUM(I14:I$23)/I$24 -> 0.0002046931 | AI15: =Y14 -> 12 | AJ15: =SUM(Z14:Z$23)/Z$24 -> 0 | AK15: =SUM(AA14:AA$23)/AA$24 -> 0 | AL15: =SUM(AB14:AB$23)/AB$24 -> 0 | AM15: =SUM(AC14:AC$23)/AC$24 -> 0 | AN15: =SUM(AD14:AD$23)/AD$24 -> 0 | AO15: =SUM(AE14:AE$23)/AE$24 -> 0 | AP15: =SUM(AF14:AF$23)/AF$24 -> 0.00041629765 | AQ15: =SUM(AG14:AG$23)/AG$24 -> 0.0002046931
K19: CFR | R19: =SUM(R7:R18) -> 1.3804762 | S19: =SUM(S7:S18) -> 1.6058907 | AI19: CFR | AP19: =SUM(AP7:AP18) -> 1.3804762 | AQ19: =SUM(AQ7:AQ18) -> 1.6058907
L21: Unprojected Parity Progression Ratios | AJ21: Unprojected Parity Progression Ratios
K22: Parity (i) | L22: 15-19 | M22: 20-24 | N22: 25-29 | O22: 30-34 | P22: 35-39 | Q22: 40-44 | R22: 45-49 | S22: 40-49 | U22: 45-49 | V22: 40-49 | AI22: Parity (i) | AJ22: 15-19 | AK22: 20-24 | AL22: 25-29 | AM22: 30-34 | AN22: 35-39 | AO22: 40-44 | AP22: 45-49 | AQ22: 40-49 | AS22: 45-49 | AT22: 40-49
K23: 0 | L23: =L7/L6 -> 1 | M23: =M7/M6 -> 0.3991153 | N23: =N7/N6 -> 0.59875777 | O23: =O7/O6 -> 0.69235394 | P23: =P7/P6 -> 0.69942003 | Q23: =Q7/Q6 -> 0.79410665 | R23: =R7/R6 -> 0.6522101 | S23: =S7/S6 -> 0.72433627 | U23: =R6 -> 1 | V23: =S6 -> 1 | AI23: 0 | AJ23: =AJ7/AJ6 -> 1 | AK23: =AK7/AK6 -> 0.3991153 | AL23: =AL7/AL6 -> 0.59875777 | AM23: =AM7/AM6 -> 0.69235394 | AN23: =AN7/AN6 -> 0.69942003 | AO23: =AO7/AO6 -> 0.79410665 | AP23: =AP7/AP6 -> 0.6522101 | AQ23: =AQ7/AQ6 -> 0.72433627 | AS23: =AP6 -> 1 | AT23: =AQ6 -> 1
A24: TOTAL | B24: =SUM(B5:B23) -> 8337.5554 | C24: =SUM(C5:C23) -> 78689.145 | D24: =SUM(D5:D23) -> 135148.43 | E24: =SUM(E5:E23) -> 203600.09 | F24: =SUM(F5:F23) -> 249347.42 | G24: =SUM(G5:G23) -> 353650.18 | H24: =SUM(H5:H23) -> 342099.22 | I24: =SUM(I5:I23) -> 695749.39 | K24: 1 | L24: =L8/L7 -> 0 | M24: =M8/M7 -> 0.21558377 | N24: =N8/N7 -> 0.63087863 | O24: =O8/O7 -> 0.44837752 | P24: =P8/P7 -> 0.53249329 | Q24: =Q8/Q7 -> 0.84316303 | R24: =R8/R7 -> 0.60905893 | S24: =S8/S7 -> 0.73951631 | U24: =PRODUCT(R$23:R23) -> 0.6522101 | V24: =PRODUCT(S$23:S23) -> 0.72433627 | Y24: TOTAL | Z24: =SUM(Z5:Z23) -> 8337.5554 | AA24: =SUM(AA5:AA23) -> 78689.145 | AB24: =SUM(AB5:AB23) -> 135148.43 | AC24: =SUM(AC5:AC23) -> 203600.09 | AD24: =SUM(AD5:AD23) -> 249347.42 | AE24: =SUM(AE5:AE23) -> 353650.18 | AF24: =SUM(AF5:AF23) -> 342099.22 | AG24: =SUM(AG5:AG23) -> 695749.39 | AI24: 1 | AJ24: =AJ8/AJ7 -> 0 | AK24: =AK8/AK7 -> 0.21558377 | AL24: =AL8/AL7 -> 0.63087863 | AM24: =AM8/AM7 -> 0.44837752 | AN24: =AN8/AN7 -> 0.53249329 | AO24: =AO8/AO7 -> 0.84316303 | AP24: =AP8/AP7 -> 0.60905893 | AQ24: =AQ8/AQ7 -> 0.73951631 | AS24: =PRODUCT(AP$23:AP23) -> 0.6522101 | AT24: =PRODUCT(AQ$23:AQ23) -> 0.72433627
A25: Average parity | B25: =SUMPRODUCT($A$5:$A$23,B5:B23)/SUM(B5:B23) -> 1 | C25: =SUMPRODUCT($A$5:$A$23,C5:C23)/SUM(C5:C23) -> 0.48515809 | D25: =SUMPRODUCT($A$5:$A$23,D5:D23)/SUM(D5:D23) -> 1.083631 | E25: =SUMPRODUCT($A$5:$A$23,E5:E23)/SUM(E5:E23) -> 1.0644329 | F25: =SUMPRODUCT($A$5:$A$23,F5:F23)/SUM(F5:F23) -> 1.2595294 | G25: =SUMPRODUCT($A$5:$A$23,G5:G23)/SUM(G5:G23) -> 1.8517545 | H25: =SUMPRODUCT($A$5:$A$23,H5:H23)/SUM(H5:H23) -> 1.3817251 | I25: =SUMPRODUCT($A$5:$A$23,I5:I23)/SUM(I5:I23) -> 1.6206416 | K25: 2 | M25: =M9/M8 -> 0 | N25: =N9/N8 -> 0.28360459 | O25: =O9/O8 -> 0.140748 | P25: =P9/P8 -> 0.41045675 | Q25: =Q9/Q8 -> 0.29244984 | R25: =R9/R8 -> 0.44544854 | S25: =S9/S8 -> 0.34823849 | U25: =PRODUCT(R$23:R24) -> 0.39723438 | V25: =PRODUCT(S$23:S24) -> 0.53565849 | Y25: Average parity | Z25: =SUMPRODUCT($Y$5:$Y$23,Z5:Z23)/SUM(Z5:Z23) -> 1 | AA25: =SUMPRODUCT($Y$5:$Y$23,AA5:AA23)/SUM(AA5:AA23) -> 0.48515809 | AB25: =SUMPRODUCT($Y$5:$Y$23,AB5:AB23)/SUM(AB5:AB23) -> 1.083631 | AC25: =SUMPRODUCT($Y$5:$Y$23,AC5:AC23)/SUM(AC5:AC23) -> 1.0644329 | AD25: =SUMPRODUCT($Y$5:$Y$23,AD5:AD23)/SUM(AD5:AD23) -> 1.2595294 | AE25: =SUMPRODUCT($Y$5:$Y$23,AE5:AE23)/SUM(AE5:AE23) -> 1.8517545 | AF25: =SUMPRODUCT($Y$5:$Y$23,AF5:AF23)/SUM(AF5:AF23) -> 1.3817251 | AG25: =SUMPRODUCT($Y$5:$Y$23,AG5:AG23)/SUM(AG5:AG23) -> 1.6206416 | AI25: 2 | AK25: =AK9/AK8 -> 0 | AL25: =AL9/AL8 -> 0.28360459 | AM25: =AM9/AM8 -> 0.140748 | AN25: =AN9/AN8 -> 0.41045675 | AO25: =AO9/AO8 -> 0.29244984 | AP25: =AP9/AP8 -> 0.44544854 | AQ25: =AQ9/AQ8 -> 0.34823849 | AS25: =PRODUCT(AP$23:AP24) -> 0.39723438 | AT25: =PRODUCT(AQ$23:AQ24) -> 0.53565849
K26: 3 | N26: =N10/N9 -> 0 | O26: =O10/O9 -> 0.20540659 | P26: =P10/P9 -> 0.22767067 | Q26: =Q10/Q9 -> 0.23768936 | R26: =R10/R9 -> 0.4665866 | S26: =S10/S9 -> 0.34445203 | U26: =PRODUCT(R$23:R25) -> 0.17694748 | V26: =PRODUCT(S$23:S25) -> 0.1865369 | AI26: 3 | AL26: =AL10/AL9 -> 0 | AM26: =AM10/AM9 -> 0.20540659 | AN26: =AN10/AN9 -> 0.22767067 | AO26: =AO10/AO9 -> 0.23768936 | AP26: =AP10/AP9 -> 0.4665866 | AQ26: =AQ10/AQ9 -> 0.34445203 | AS26: =PRODUCT(AP$23:AP25) -> 0.17694748 | AT26: =PRODUCT(AQ$23:AQ25) -> 0.1865369
K27: 4 | O27: =O11/O10 -> 1 | P27: =P11/P10 -> 0 | Q27: =Q11/Q10 -> 0.79025574 | R27: =R11/R10 -> 0.76657153 | S27: =S11/S10 -> 0.77529196 | U27: =PRODUCT(R$23:R26) -> 0.082561321 | V27: =PRODUCT(S$23:S26) -> 0.064253014 | AI27: 4 | AM27: =AM11/AM10 -> 1 | AN27: =AN11/AN10 -> 0 | AO27: =AO11/AO10 -> 0.79025574 | AP27: =AP11/AP10 -> 0.76657153 | AQ27: =AQ11/AQ10 -> 0.77529196 | AS27: =PRODUCT(AP$23:AP26) -> 0.082561321 | AT27: =PRODUCT(AQ$23:AQ26) -> 0.064253014
K28: 5 | Q28: =Q12/Q11 -> 0.75615667 | R28: =R12/R11 -> 0.11036475 | S28: =S12/S11 -> 0.35273206 | U28: =PRODUCT(R$23:R27) -> 0.063289159 | V28: =PRODUCT(S$23:S27) -> 0.049814845 | AI28: 5 | AO28: =AO12/AO11 -> 0.75615667 | AP28: =AP12/AP11 -> 0.11036475 | AQ28: =AQ12/AQ11 -> 0.35273206 | AS28: =PRODUCT(AP$23:AP27) -> 0.063289159 | AT28: =PRODUCT(AQ$23:AQ27) -> 0.049814845
K29: 6 | Q29: =Q13/Q12 -> 1 | R29: =R13/R12 -> 0.059599726 | S29: =S13/S12 -> 0.81619049 | U29: =PRODUCT(R$23:R28) -> 0.006984892 | V29: =PRODUCT(S$23:S28) -> 0.017571293 | AI29: 6 | AO29: =AO13/AO12 -> 1 | AP29: =AP13/AP12 -> 0.059599726 | AQ29: =AQ13/AQ12 -> 0.81619049 | AS29: =PRODUCT(AP$23:AP28) -> 0.006984892 | AT29: =PRODUCT(AQ$23:AQ28) -> 0.017571293
K30: 8 | Q30: =Q14/Q13 -> 0.91738676 | R30: =R14/R13 -> 1 | S30: =S14/S13 -> 0.91856588 | U30: =PRODUCT(R$23:R29) -> 0.00041629765 | V30: =PRODUCT(S$23:S29) -> 0.014341522 | AI30: 8 | AO30: =AO14/AO13 -> 0.91738676 | AP30: =AP14/AP13 -> 1 | AQ30: =AQ14/AQ13 -> 0.91856588 | AS30: =PRODUCT(AP$23:AP29) -> 0.00041629765 | AT30: =PRODUCT(AQ$23:AQ29) -> 0.014341522
K31: 9 | Q31: =Q15/Q14 -> 0 | R31: =R15/R14 -> 1 | S31: =S15/S14 -> 0.01553809 | U31: =PRODUCT(R$23:R30) -> 0.00041629765 | V31: =PRODUCT(S$23:S30) -> 0.013173633 | AI31: 9 | AO31: =AO15/AO14 -> 0 | AP31: =AP15/AP14 -> 1 | AQ31: =AQ15/AQ14 -> 0.01553809 | AS31: =PRODUCT(AP$23:AP30) -> 0.00041629765 | AT31: =PRODUCT(AQ$23:AQ30) -> 0.013173633
K32: 12 | R32: =R16/R15 -> 0 | S32: =S16/S15 -> 0 | U32: =PRODUCT(R$23:R31) -> 0.00041629765 | V32: =PRODUCT(S$23:S31) -> 0.0002046931 | AI32: 12 | AP32: =AP16/AP15 -> 0 | AQ32: =AQ16/AQ15 -> 0 | AS32: =PRODUCT(AP$23:AP31) -> 0.00041629765 | AT32: =PRODUCT(AQ$23:AQ31) -> 0.0002046931
U33: =PRODUCT(R$23:R32) -> 0 | V33: =PRODUCT(S$23:S32) -> 0 | AS33: =PRODUCT(AP$23:AP32) -> 0 | AT33: =PRODUCT(AQ$23:AQ32) -> 0
V34: =SUM(V24:V33) -> 1.6058907 | AT34: =SUM(AT24:AT33) -> 1.6058907
T36: CFR | U36: =SUM(U24:U33) -> 1.3804762 | V36: =SUM(V24:V33) -> 1.6058907 | AR36: CFR | AS36: =SUM(AS24:AS33) -> 1.3804762 | AT36: =SUM(AT24:AT33) -> 1.6058907

Sheet PPR tidos
H1: ============================ | O1: ============================
A2: ============================ | H2: == | I2: Subgrupo: | J2: mu | O2: == | P2: Subgrupo: | Q2: mu
A3: == | B3: Subgrupo: | C3: mu | H3: ============================ | O3: ============================
A4: ============================
H5: --- | I5: Resumo | J5: (junta_df) | K5: --- | O5: --- | P5: Resumo | Q5: (junta_df) | R5: ---
A6: --- | B6: Resumo | C6: (junta_df) | D6: --- | I6: Age | J6: AverageParity | K6: CTFR_pprs | L6: CTFR_prop | P6: Age | Q6: AverageParity | R6: CTFR_pprs | S6: CTFR_prop
B7: Age | C7: AverageParity | D7: CTFR_pprs | E7: CTFR_prop | H7: 1 | I7: <20 | J7: 0.186 | K7: 0.186 | L7: 0.1858 | O7: 1 | P7: <20 | Q7: 0.186 | R7: 0.186 | S7: 0.1858
A8: 1 | B8: <20 | C8: 0.186 | D8: 0.186 | E8: 0.1858 | H8: 2 | I8: 20-29 | J8: 0.997 | K8: 0.997 | L8: 0.9968 | O8: 2 | P8: 20-34 | Q8: 1.244 | R8: 1.244 | S8: 1.2443
A9: 2 | B9: 20-24 | C9: 0.743 | D9: 0.743 | E9: 0.7427 | H9: 3 | I9: 30-39 | J9: 1.933 | K9: 1.933 | L9: 1.9327 | O9: 3 | P9: 35-49 | Q9: 2.339 | R9: 2.339 | S9: 2.3394
A10: 3 | B10: 25-29 | C10: 1.271 | D10: 1.271 | E10: 1.2708 | H10: 4 | I10: 40-49 | J10: 2.495 | K10: 2.495 | L10: 2.4953
A11: 4 | B11: 30-34 | C11: 1.812 | D11: 1.812 | E11: 1.8118 | O11: --- | P11: All Women | Q11: (35-49) | R11: i | S11: = | T11: 1..4 | U11: ---
A12: 5 | B12: 35-39 | C12: 2.057 | D12: 2.057 | E12: 2.0567 | H12: --- | I12: All Women | J12: (40-49) | K12: i | L12: = | M12: 1..4 | N12: --- | P12: Parity | Q12: PPR | R12: desejados
A13: 6 | B13: 40-44 | C13: 2.382 | D13: 2.382 | E13: 2.3821 | I13: Parity | J13: PPR_mu | K13: desejados | O13: 1 | P13: 0-1 | Q13: 0.8785359 | R13: ='PPR desejados'!Q13 -> 0.9313593
A14: 7 | B14: 45-49 | C14: 2.627 | D14: 2.627 | E14: 2.6273 | H14: 1 | I14: 0-1 | J14: 0.8863531 | K14: ='PPR desejados'!J14 -> 0.9320715 | O14: 2 | P14: 1-2 | Q14: 0.7876608 | R14: ='PPR desejados'!Q14 -> 0.8527571
H15: 2 | I15: 1-2 | J15: 0.8140187 | K15: ='PPR desejados'!J15 -> 0.8571591 | O15: 3 | P15: 2-3 | Q15: 0.5303733 | R15: ='PPR desejados'!Q15 -> 0.421292
A16: --- | B16: All Women | C16: (45-49) | D16: i | E16: = | F16: 1..4 | G16: --- | H16: 3 | I16: 2-3 | J16: 0.5565124 | K16: ='PPR desejados'!J16 -> 0.4465682 | O16: 4 | P16: 3-4 | Q16: 0.4853048 | R16: ='PPR desejados'!Q16 -> 0.4443761
B17: Parity | C17: tidos | D17: desejados | H17: 4 | I17: 3-4 | J17: 0.5045849 | K17: ='PPR desejados'!J17 -> 0.4793581
A18: 1 | B18: 0-1 | C18: 0.8655703 | D18: ='PPR desejados'!C17 -> 0.9206525 | O18: ============================
A19: 2 | B19: 1-2 | C19: 0.8351048 | D19: ='PPR desejados'!C18 -> 0.8514769 | H19: ============================ | O19: == | P19: Subgrupo: | Q19: pub
A20: 3 | B20: 2-3 | C20: 0.6015555 | D20: ='PPR desejados'!C19 -> 0.4611487 | H20: == | I20: Subgrupo: | J20: pub | O20: ============================
A21: 4 | B21: 3-4 | C21: 0.5574857 | D21: ='PPR desejados'!C20 -> 0.5150369 | H21: ============================
O22: --- | P22: Resumo | Q22: (junta_df) | R22: ---
A23: ============================ | H23: --- | I23: Resumo | J23: (junta_df) | K23: --- | P23: Age | Q23: AverageParity | R23: CTFR_pprs | S23: CTFR_prop
A24: == | B24: Subgrupo: | C24: pub | I24: Age | J24: AverageParity | K24: CTFR_pprs | L24: CTFR_prop | O24: 1 | P24: <20 | Q24: 1 | R24: 1 | S24: 1
A25: ============================ | H25: 1 | I25: <20 | J25: 1 | K25: 1 | L25: 1 | O25: 2 | P25: 20-34 | Q25: 0.961 | R25: 0.961 | S25: 0.9615
H26: 2 | I26: 20-29 | J26: 0.863 | K26: 0.863 | L26: 0.8634 | O26: 3 | P26: 35-49 | Q26: 1.525 | R26: 1.515 | S26: 1.5147
A27: --- | B27: Resumo | C27: (junta_df) | D27: --- | H27: 3 | I27: 30-39 | J27: 1.172 | K27: 1.172 | L27: 1.1718
B28: Age | C28: AverageParity | D28: CTFR_pprs | E28: CTFR_prop | H28: 4 | I28: 40-49 | J28: 1.621 | K28: 1.606 | L28: 1.6059 | O28: --- | P28: Public | Q28: (35-49) | R28: i | S28: = | T28: 1..4 | U28: ---
A29: 1 | B29: <20 | C29: 1 | D29: 1 | E29: 1 | P29: Parity | Q29: PPR | R29: desejados
A30: 2 | B30: 20-24 | C30: 0.485 | D30: 0.485 | E30: 0.4851 | H30: --- | I30: Public | J30: (40-49) | K30: i | L30: = | M30: 1..4 | N30: --- | O30: 1 | P30: 0-1 | Q30: 0.7177626 | R30: ='PPR desejados'!Q30 -> 0.9154161
A31: 3 | B31: 25-29 | C31: 1.084 | D31: 1.084 | E31: 1.0836 | I31: Parity | J31: PPR_pub | K31: desejados | O31: 2 | P31: 1-2 | Q31: 0.6862927 | R31: ='PPR desejados'!Q31 -> 0.8310429
A32: 4 | B32: 30-34 | C32: 1.064 | D32: 1.064 | E32: 1.0645 | H32: 1 | I32: 0-1 | J32: 0.7243363 | K32: ='PPR desejados'!J32 -> 0.9238399 | O32: 3 | P32: 2-3 | Q32: 0.3606495 | R32: ='PPR desejados'!Q32 -> 0.3677907
A33: 5 | B33: 35-39 | C33: 1.26 | D33: 1.26 | E33: 1.2595 | H33: 2 | I33: 1-2 | J33: 0.7395163 | K33: ='PPR desejados'!J33 -> 0.8568922 | O33: 4 | P33: 3-4 | Q33: 0.3179398 | R33: ='PPR desejados'!Q33 -> 0.377752
A34: 6 | B34: 40-44 | C34: 1.852 | D34: 1.824 | E34: 1.8239 | H34: 3 | I34: 2-3 | J34: 0.3482385 | K34: ='PPR desejados'!J34 -> 0.3585101
A35: 7 | B35: 45-49 | C35: 1.382 | D35: 1.38 | E35: 1.3804 | H35: 4 | I35: 3-4 | J35: 0.344452 | K35: ='PPR desejados'!J35 -> 0.4550351 | O35: ============================
O36: == | P36: Subgrupo: | Q36: yes
A37: --- | B37: Public | C37: (45-49) | D37: i | E37: = | F37: 1..4 | G37: --- | H37: ============================ | O37: ============================
B38: Parity | C38: PPR | D38: desejados | H38: == | I38: Subgrupo: | J38: yes
A39: 1 | B39: 0-1 | C39: 0.6522101 | D39: ='PPR desejados'!C38 -> 0.8984116 | H39: ============================ | O39: --- | P39: Resumo | Q39: (junta_df) | R39: ---
A40: 2 | B40: 1-2 | C40: 0.6090589 | D40: ='PPR desejados'!C39 -> 0.8138817 | P40: Age | Q40: AverageParity | R40: CTFR_pprs | S40: CTFR_prop
...

Sheet PPR desejados
A1: ============================ | H1: ============================ | O1: ============================
A2: == | B2: Subgrupo: | C2: mu | H2: == | I2: Subgrupo: | J2: mu | O2: == | P2: Subgrupo: | Q2: mu
A3: ============================ | H3: ============================ | O3: ============================
A5: --- | B5: Resumo | C5: (junta_df) | D5: --- | H5: --- | I5: Resumo | J5: (junta_df) | K5: --- | O5: --- | P5: Resumo | Q5: (junta_df) | R5: ---
B6: Age | C6: AverageParity | D6: CTFR_pprs | E6: CTFR_prop | I6: Age | J6: AverageParity | K6: CTFR_pprs | L6: CTFR_prop | P6: Age | Q6: AverageParity | R6: CTFR_pprs | S6: CTFR_prop
A7: 1 | B7: <20 | C7: 1.868 | D7: 1.868 | E7: 1.8685 | H7: 1 | I7: <20 | J7: 1.868 | K7: 1.868 | L7: 1.8685 | O7: 1 | P7: <20 | Q7: 1.868 | R7: 1.868 | S7: 1.8685
A8: 2 | B8: 20-24 | C8: 1.867 | D8: 1.867 | E8: 1.8666 | H8: 2 | I8: 20-29 | J8: 1.892 | K8: 1.892 | L8: 1.8923 | O8: 2 | P8: 20-34 | Q8: 1.951 | R8: 1.951 | S8: 1.9514
A9: 3 | B9: 25-29 | C9: 1.92 | D9: 1.92 | E9: 1.9202 | H9: 3 | I9: 30-39 | J9: 2.144 | K9: 2.144 | L9: 2.1442 | O9: 3 | P9: 35-49 | Q9: 2.372 | R9: 2.371 | S9: 2.3714
A10: 4 | B10: 30-34 | C10: 2.086 | D10: 2.086 | E10: 2.0861 | H10: 4 | I10: 40-49 | J10: 2.466 | K10: 2.465 | L10: 2.4653
A11: 5 | B11: 35-39 | C11: 2.204 | D11: 2.204 | E11: 2.2038 | O11: --- | P11: PPR | Q11: (35-49) | R11: i | S11: = | T11: 1..4 | U11: ---
A12: 6 | B12: 40-44 | C12: 2.423 | D12: 2.422 | E12: 2.4223 | H12: --- | I12: PPR | J12: (40-49) | K12: i | L12: = | M12: 1..4 | N12: --- | P12: Parity | Q12: PPR
A13: 7 | B13: 45-49 | C13: 2.517 | D13: 2.515 | E13: 2.515 | I13: Parity | J13: PPR | O13: 1 | P13: 1 | Q13: 0.9313593
H14: 1 | I14: 1 | J14: 0.9320715 | O14: 2 | P14: 2 | Q14: 0.8527571
A15: --- | B15: PPR | C15: (45-49) | D15: i | E15: = | F15: 1..4 | G15: --- | H15: 2 | I15: 2 | J15: 0.8571591 | O15: 3 | P15: 3 | Q15: 0.421292
B16: Parity | C16: PPR_mu | H16: 3 | I16: 3 | J16: 0.4465682 | O16: 4 | P16: 4 | Q16: 0.4443761
A17: 1 | B17: 1 | C17: 0.9206525 | H17: 4 | I17: 4 | J17: 0.4793581
A18: 2 | B18: 2 | C18: 0.8514769 | O18: ============================
A19: 3 | B19: 3 | C19: 0.4611487 | H19: ============================ | O19: == | P19: Subgrupo: | Q19: pub
A20: 4 | B20: 4 | C20: 0.5150369 | H20: == | I20: Subgrupo: | J20: pub | O20: ============================
H21: ============================
A22: ============================ | O22: --- | P22: Resumo | Q22: (junta_df) | R22: ---
A23: == | B23: Subgrupo: | C23: pub | H23: --- | I23: Resumo | J23: (junta_df) | K23: --- | P23: Age | Q23: AverageParity | R23: CTFR_pprs | S23: CTFR_prop
A24: ============================ | I24: Age | J24: AverageParity | K24: CTFR_pprs | L24: CTFR_prop | O24: 1 | P24: <20 | Q24: 2 | R24: 2 | S24: 2
H25: 1 | I25: <20 | J25: 2 | K25: 2 | L25: 2 | O25: 2 | P25: 20-34 | Q25: 1.946 | R25: 1.946 | S25: 1.9459
A26: --- | B26: Resumo | C26: (junta_df) | D26: --- | H26: 2 | I26: 20-29 | J26: 1.845 | K26: 1.845 | L26: 1.8448 | O26: 3 | P26: 35-49 | Q26: 2.204 | R26: 2.174 | S26: 2.1737
B27: Age | C27: AverageParity | D27: CTFR_pprs | E27: CTFR_prop | H27: 3 | I27: 30-39 | J27: 1.964 | K27: 1.964 | L27: 1.9645
A28: 1 | B28: <20 | C28: 2 | D28: 2 | E28: 2 | H28: 4 | I28: 40-49 | J28: 2.321 | K28: 2.279 | L28: 2.2788 | O28: --- | P28: PPR | Q28: (35-49) | R28: i | S28: = | T28: 1..4 | U28: ---
A29: 2 | B29: 20-24 | C29: 1.601 | D29: 1.601 | E29: 1.601 | P29: Parity | Q29: PPR
A30: 3 | B30: 25-29 | C30: 1.995 | D30: 1.995 | E30: 1.9952 | H30: --- | I30: PPR | J30: (40-49) | K30: i | L30: = | M30: 1..4 | N30: --- | O30: 1 | P30: 1 | Q30: 0.9154161
A31: 4 | B31: 30-34 | C31: 2.049 | D31: 2.049 | E31: 2.0486 | I31: Parity | J31: PPR | O31: 2 | P31: 2 | Q31: 0.8310429
A32: 5 | B32: 35-39 | C32: 1.896 | D32: 1.896 | E32: 1.8956 | H32: 1 | I32: 1 | J32: 0.9238399 | O32: 3 | P32: 3 | Q32: 0.3677907
A33: 6 | B33: 40-44 | C33: 2.508 | D33: 2.452 | E33: 2.4525 | H33: 2 | I33: 2 | J33: 0.8568922 | O33: 4 | P33: 4 | Q33: 0.377752
A34: 7 | B34: 45-49 | C34: 2.105 | D34: 2.077 | E34: 2.0769 | H34: 3 | I34: 3 | J34: 0.3585101
H35: 4 | I35: 4 | J35: 0.4550351 | O35: ============================
A36: --- | B36: PPR | C36: (45-49) | D36: i | E36: = | F36: 1..4 | G36: --- | O36: == | P36: Subgrupo: | Q36: yes
B37: Parity | C37: PPR_pub | H37: ============================ | O37: ============================
A38: 1 | B38: 1 | C38: 0.8984116 | H38: == | I38: Subgrupo: | J38: yes
A39: 2 | B39: 2 | C39: 0.8138817 | H39: ============================ | O39: --- | P39: Resumo | Q39: (junta_df) | R39: ---
A40: 3 | B40: 3 | C40: 0.3333078 | P40: Age | Q40: AverageParity | R40: CTFR_pprs | S40: CTFR_prop
A41: 4 | B41: 4 | C41: 0.3896337 | H41: --- | I41: Resumo | J41: (junta_df) | K41: --- | O41: 1 | P41: <20 | Q41: 1.997 | R41: 1.997 | S41: 1.997
...

Sheet mulheres
A1: > | B1: svytable(~addNA(M712_CART) | C1: design | D1: = | E1: mu)
A2: addNA(M712_CART)
B3: 1 | C3: 2 | D3: 3 | E3: 95 | F3: <NA>
B4: 11873344 | C4: 21155353 | D4: 1370872 | E4: 73393.8 | F4: 17888493
A7: idade_categ
B8: <20 | C8: 20-24 | D8: 25-29 | E8: 30-34 | F8: 35-39 | G8: 40-44 | H8: 45-49 | I8: Total
B9: 8417796 | C9: 8660654 | D9: 8023502 | E9: 7276364 | F9: 7097828 | G9: 6947801 | H9: 5937511 | I9: =SUM(B9:H9) -> 52361456
A12: > | B12: svytable(~CM008_SITU+idade_categ | C12: design | D12: = | E12: mu)
B13: idade_categ
A14: CM008_SITU | C14: <20 | D14: 20-24 | E14: 25-29 | F14: 30-34 | G14: 35-39 | H14: 40-44 | I14: 45-49 | J14: total
B15: 1 | C15: 6880481.3 | D15: 7147455 | E15: 6748987.1 | F15: 6152921.7 | G15: 6031203 | H15: 5786108 | I15: 5081694.3 | J15: =SUM(C15:I15) -> 43828850 | K15: =J15/$I$9 -> 0.83704415
B16: 2 | C16: 1537314.8 | D16: 1513199.2 | E16: 1274514.8 | F16: 1123442.1 | G16: 1066625.3 | H16: 1161692.5 | I16: 855817.1 | J16: =SUM(C16:I16) -> 8532605.8 | K16: =J16/$I$9 -> 0.16295585
A19: > | B19: svytable(~CM004_MACR+idade_categ | C19: design | D19: = | E19: mu)
B20: idade_categ
A21: CM004_MACR | C21: <20 | D21: 20-24 | E21: 25-29 | F21: 30-34 | G21: 35-39 | H21: 40-44 | I21: 45-49 | J21: total
B22: 1 | C22: 747944.7 | D22: 718881.5 | E22: 637721.7 | F22: 599902.5 | G22: 479944 | H22: 412261.1 | I22: 280600.8 | J22: =SUM(C22:I22) -> 3877256.3 | K22: =J22/$I$9 -> 0.074047908
B23: 2 | C23: 2541140.1 | D23: 2390808.1 | E23: 2234308.6 | F23: 1868657.8 | G23: 1794270.1 | H23: 1571375.2 | I23: 1421764.3 | J23: =SUM(C23:I23) -> 13822324 | K23: =J23/$I$9 -> 0.26397899
B24: 3 | C24: 3380772.2 | D24: 3834307.7 | E24: 3403946.2 | F24: 3170723 | G24: 3332925.7 | H24: 3156997 | I24: 2796194 | J24: =SUM(C24:I24) -> 23075866 | K24: =J24/$I$9 -> 0.44070329
B25: 4 | C25: 1165220.6 | D25: 1100138.6 | E25: 1167287 | F25: 1113891.2 | G25: 960148.1 | H25: 1275012.1 | I25: 998188.2 | J25: =SUM(C25:I25) -> 7779885.8 | K25: =J25/$I$9 -> 0.14858039
B26: 5 | C26: 582718.4 | D26: 616518.3 | E26: 580238.4 | F26: 523189.2 | G26: 530540.4 | H26: 532155.1 | I26: 440764.2 | J26: =SUM(C26:I26) -> 3806124 | K26: =J26/$I$9 -> 0.072689423
A28: > | B28: svytable(~escolarizacao_cat+idade_categ | C28: design | D28: = | E28: mu)
B29: idade_categ
A30: escolarizacao_cat | C30: <20 | D30: 20-24 | E30: 25-29 | F30: 30-34 | G30: 35-39 | H30: 40-44 | I30: 45-49 | J30: total
B31: <8 | C31: 2475865.4 | D31: 2018834.8 | E31: 2623450.7 | F31: 2588101 | G31: 2846353.1 | H31: 3129908.8 | I31: 3206123.6 | J31: =SUM(C31:I31) -> 18888637 | K31: =J31/$I$9 -> 0.36073553
B32: 45969 | C32: 5648637.1 | D32: 5459932.5 | E32: 4080871.7 | F32: 3546276.2 | G32: 3091456 | H32: 2829245.5 | I32: 1813221.8 | J32: =SUM(C32:I32) -> 26469641 | K32: =J32/$I$9 -> 0.50551766
B33: 12+ | C33: 246125.1 | D33: 1101211.2 | E33: 1234738.4 | F33: 1099988.9 | G33: 1110661.9 | H33: 936292.9 | I33: 821358.6 | J33: =SUM(C33:I33) -> 6550377 | K33: =J33/$I$9 -> 0.12509921
A35: > | B35: svytable(~etnia_cat+idade_categ | C35: design | D35: = | E35: mu)
B36: idade_categ
A37: etnia_cat | C37: <20 | D37: 20-24 | E37: 25-29 | F37: 30-34 | G37: 35-39 | H37: 40-44 | I37: 45-49 | J37: total
B38: Branca | C38: 2978255 | D38: 3348152.9 | E38: 3019700.7 | F38: 2864515.6 | G38: 2903187.3 | H38: 3073902.9 | I38: 2686201.7 | J38: =SUM(C38:I38) -> 20873916 | K38: =J38/$I$9 -> 0.39865041
B39: Negra | C39: 4766161.2 | D39: 4688728.7 | E39: 4467841.6 | F39: 4003088.6 | G39: 3827348.1 | H39: 3518047.6 | I39: 2998907 | J39: =SUM(C39:I39) -> 28270123 | K39: =J39/$I$9 -> 0.5399033
B40: Outra | C40: 598786.9 | D40: 556877.3 | E40: 429450 | F40: 352412.3 | G40: 314293.4 | H40: 263925.8 | I40: 199427.2 | J40: =SUM(C40:I40) -> 2715172.9 | K40: =J40/$I$9 -> 0.051854419

Sheet resumo
B2: Characteristics | C2: number of Women (Weighted data) | E2: % | N2: Characteristics | O2: CTFR (achived) | P2: CTFR (desired) | Q2: % of women with no children
C3: all women | D3: public servants | E3: all women | F3: public servants | N3: Total
B4: Total | C4: =mulheres!I9 -> 52361456 | D4: =[1]resumo!C3 -> 1370872 | E4: 1 | F4: =[1]resumo!D3 -> 1 | N4: Household location
B5: Household location | N5: Urban
B6: Urban | C6: =mulheres!J15 -> 43828850 | D6: =[1]resumo!C5 -> 1236773 | E6: =mulheres!K15 -> 0.83704415 | F6: =[1]resumo!D5 -> 0.90217977 | N6: Rural
B7: Rural | C7: =mulheres!J16 -> 8532605.8 | D7: =[1]resumo!C6 -> 134099.01 | E7: =mulheres!K16 -> 0.16295585 | F7: =[1]resumo!D6 -> 0.097820227 | N7: Region
B8: Region | N8: North
B9: North | C9: =mulheres!J22 -> 3877256.3 | D9: =[1]resumo!C8 -> 109218.71 | E9: =mulheres!K22 -> 0.074047908 | F9: =[1]resumo!D8 -> 0.079670977 | N9: Northeast
B10: Northeast | C10: =mulheres!J23 -> 13822324 | D10: =[1]resumo!C9 -> 239070.29 | E10: =mulheres!K23 -> 0.26397899 | F10: =[1]resumo!D9 -> 0.17439286 | N10: Southeast
B11: Southeast | C11: =mulheres!J24 -> 23075866 | D11: =[1]resumo!C10 -> 610527.33 | E11: =mulheres!K24 -> 0.44070329 | F11: =[1]resumo!D10 -> 0.44535691 | N11: South
B12: South | C12: =mulheres!J25 -> 7779885.8 | D12: =[1]resumo!C11 -> 291846.94 | E12: =mulheres!K25 -> 0.14858039 | F12: =[1]resumo!D11 -> 0.21289145 | N12: Central-West
B13: Central-West | C13: =mulheres!J26 -> 3806124 | D13: =[1]resumo!C12 -> 120208.76 | E13: =mulheres!K26 -> 0.072689423 | F13: =[1]resumo!D12 -> 0.087687807 | N13: Education
B14: Education | N14: Up to 8 years
B15: Up to 7 years | C15: =mulheres!J31 -> 18888637 | D15: =[1]resumo!C14 -> 122900.57 | E15: =mulheres!K31 -> 0.36073553 | F15: =[1]resumo!D14 -> 0.089683254 | N15: 9–11 years
B16: 8–11 years | C16: =mulheres!J32 -> 26469641 | D16: =[1]resumo!C15 -> 461148.44 | E16: =mulheres!K32 -> 0.50551766 | F16: =[1]resumo!D15 -> 0.33651019 | N16: 12 or more years
B17: 12 or more years | C17: =mulheres!J33 -> 6550377 | D17: =[1]resumo!C16 -> 786335.76 | E17: =mulheres!K33 -> 0.12509921 | F17: =[1]resumo!D16 -> 0.57380655 | N17: Ethnicity
B18: Ethnicity | N18: White
B19: White | C19: =mulheres!J38 -> 20873916 | D19: =[1]resumo!C18 -> 700554.37 | E19: =mulheres!K38 -> 0.39865041 | F19: =[1]resumo!D18 -> 0.51507104 | N19: Black
B20: Black | C20: =mulheres!J39 -> 28270123 | D20: =[1]resumo!C19 -> 610856.02 | E20: =mulheres!K39 -> 0.5399033 | F20: =[1]resumo!D19 -> 0.4491218 | N20: Other
B21: Other | C21: =mulheres!J40 -> 2715172.9 | D21: =[1]resumo!C20 -> 48701.755 | E21: =mulheres!K40 -> 0.051854419 | F21: =[1]resumo!D20 -> 0.035807161
O22: =desejados!C4 -> <20 | P22: =desejados!D4 -> 20-24 | Q22: =desejados!E4 -> 25-29 | R22: =desejados!F4 -> 30-34 | S22: =desejados!G4 -> 35-39 | T22: =desejados!H4 -> 40-44
N23: Mean intended number | O23: =desejados!D23 -> 1.8666804 | P23: =desejados!E23 -> 1.9202251 | Q23: =desejados!F23 -> 2.0861798 | R23: =desejados!G23 -> 2.2040976 | S23: =desejados!H23 -> 2.4231515 | T23: =desejados!I23 -> 2.5170012
N24: Mean actual number | O24: =nascidos!C23 -> 0.18578847 | P24: =nascidos!D23 -> 0.74276584 | Q24: =nascidos!E23 -> 1.2707499 | R24: =nascidos!F23 -> 1.8116451 | S24: =nascidos!G23 -> 2.0568047 | T24: =nascidos!H23 -> 2.3819344
N25: Difference | O25: =O23-O24 -> 1.6808919 | P25: =P23-P24 -> 1.1774592 | Q25: =Q23-Q24 -> 0.81542981 | R25: =R23-R24 -> 0.39245247 | S25: =S23-S24 -> 0.36634681 | T25: =T23-T24 -> 0.1350668
B28: Marital status | C28: Single (never married) | D28: Currently married (civil marriage) | E28: Currently living together (consensual union) | F28: Widowed | G28: Separated | H28: Legally separated (de facto separated) | I28: Divorced | J28: Indeterminate / Not specified | K28: total
A29: Weighted data | B29: All Women | C29: 13486168 | D29: 19226004 | E29: 14288390 | F29: 706341.84 | G29: 3893959 | H29: 103432.86 | I29: 610026.45 | J29: 47134.02 | K29: =SUM(C29:J29) -> 52361456
B30: Public servants | C30: =[1]descritiva!E14 -> 316287.44 | D30: =[1]descritiva!F14 -> 604590.04 | E30: =[1]descritiva!G14 -> 233160.54 | F30: =[1]descritiva!H14 -> 28820.761 | G30: =[1]descritiva!I14 -> 128289.57 | H30: =[1]descritiva!J14 -> 2630.997 | I30: =[1]descritiva!K14 -> 57092.683 | J30: =[1]descritiva!L14 -> 0 | K30: =[1]descritiva!M14 -> 1370872
A31: % | B31: All Women | C31: =C29/SUM($C$29:$J$29) -> 0.25755906 | D31: =D29/SUM($C$29:$J$29) -> 0.36717856 | E31: =E29/SUM($C$29:$J$29) -> 0.27287993 | F31: =F29/SUM($C$29:$J$29) -> 0.013489729 | G31: =G29/SUM($C$29:$J$29) -> 0.074366896 | H31: =H29/SUM($C$29:$J$29) -> 0.0019753626 | I31: =I29/SUM($C$29:$J$29) -> 0.011650296 | J31: =J29/SUM($C$29:$J$29) -> 0.00090016633 | K31: =K29/SUM($C$29:$J$29) -> 1
B32: Public servants | C32: =[1]descritiva!E15 -> 0.23071988 | D32: =[1]descritiva!F15 -> 0.44102588 | E32: =[1]descritiva!G15 -> 0.17008192 | F32: =[1]descritiva!H15 -> 0.02102367 | G32: =[1]descritiva!I15 -> 0.093582458 | H32: =[1]descritiva!J15 -> 0.0019192141 | I32: =[1]descritiva!K15 -> 0.041646982 | J32: =[1]descritiva!L15 -> 0 | K32: =[1]descritiva!M15 -> 1

Sheet PPR Resumo
A3: Considering Women aged 45-49
B4: All Women | D4: Public Servants | F4: With formal contract | H4: Without formal contract
A5: Parity | B5: Actual | C5: Intended | D5: Actual | E5: Intended | F5: Actual | G5: Intended | H5: Actual | I5: Intended
A6: 0–1 | B6: 0.866 | C6: 0.921 | D6: 0.652 | E6: 0.898 | F6: 0.851 | G6: 0.879 | H6: 0.87 | I6: 0.927
A7: 1–2 | B7: 0.835 | C7: 0.851 | D7: 0.609 | E7: 0.814 | F7: 0.825 | G7: 0.871 | H7: 0.828 | I7: 0.859
A8: 2–3 | B8: 0.602 | C8: 0.461 | D8: 0.445 | E8: 0.333 | F8: 0.502 | G8: 0.345 | H8: 0.672 | I8: 0.525
A9: 3–4 | B9: 0.557 | C9: 0.515 | D9: 0.467 | E9: 0.39 | F9: 0.417 | G9: 0.427 | H9: 0.598 | I9: 0.53
A11: Considering Women aged 40-49
B12: All Women | D12: Public Servants | F12: With formal contract | H12: Without formal contract
A13: Parity | B13: Actual | C13: Intended | D13: Actual | E13: Intended | F13: Actual | G13: Intended | H13: Actual | I13: Intended
A14: 0–1 | B14: 0.886 | C14: 0.932 | D14: 0.724 | E14: 0.924 | F14: 0.865 | G14: 0.911 | H14: 0.89 | I14: 0.933
A15: 1–2 | B15: 0.814 | C15: 0.857 | D15: 0.74 | E15: 0.857 | F15: 0.748 | G15: 0.849 | H15: 0.842 | I15: 0.863
A16: 2–3 | B16: 0.557 | C16: 0.447 | D16: 0.348 | E16: 0.359 | F16: 0.46 | G16: 0.392 | H16: 0.609 | I16: 0.476
A17: 3–4 | B17: 0.505 | C17: 0.479 | D17: 0.344 | E17: 0.455 | F17: 0.372 | G17: 0.436 | H17: 0.51 | I17: 0.483
A19: Considering Women aged 35-49
B20: All Women | D20: Public Servants | F20: With formal contract | H20: Without formal contract
A21: Parity | B21: Actual | C21: Intended | D21: Actual | E21: Intended | F21: Actual | G21: Intended | H21: Actual | I21: Intended
A22: 0–1 | B22: 0.879 | C22: 0.931 | D22: 0.718 | E22: 0.915 | F22: 0.831 | G22: 0.922 | H22: 0.895 | I22: 0.928
A23: 1–2 | B23: 0.788 | C23: 0.853 | D23: 0.686 | E23: 0.831 | F23: 0.728 | G23: 0.85 | H23: 0.812 | I23: 0.861
A24: 2–3 | B24: 0.53 | C24: 0.421 | D24: 0.361 | E24: 0.368 | F24: 0.423 | G24: 0.344 | H24: 0.564 | I24: 0.441
A25: 3–4 | B25: 0.485 | C25: 0.444 | D25: 0.318 | E25: 0.378 | F25: 0.366 | G25: 0.42 | H25: 0.489 | I25: 0.436
B27: All Women | C27: Public Servants | D27: With formal contract | E27: Without formal contract
B28: =C14-B14 -> 0.046 | C28: =E14-D14 -> 0.2 | D28: =G14-F14 -> 0.046 | E28: =I14-H14 -> 0.043
B29: =C15-B15 -> 0.043 | C29: =E15-D15 -> 0.117 | D29: =G15-F15 -> 0.101 | E29: =I15-H15 -> 0.021
B30: =C16-B16 -> -0.11 | C30: =E16-D16 -> 0.011 | D30: =G16-F16 -> -0.068 | E30: =I16-H16 -> -0.133
B31: =C17-B17 -> -0.026 | C31: =E17-D17 -> 0.111 | D31: =G17-F17 -> 0.064 | E31: =I17-H17 -> -0.027

Sheet summary
A1: Category | B1: Women (%) | C1: Formal contract (%) | D1: No formal contract (%) | E1: Public servants (%)
A2: Age group
A3: < 20 years | B3: 16.1 | C3: 5.4 | D3: 14.5 | E3: 0.6
A4: 20–24 years | B4: 16.5 | C4: 17.9 | D4: 16.4 | E4: 5.7
A5: 25–29 years | B5: 15.3 | C5: 19.8 | D5: 15.5 | E5: 9.9
A6: 30–34 years | B6: 13.9 | C6: 15.6 | D6: 14.5 | E6: 14.9
A7: 35–39 years | B7: 13.6 | C7: 15.7 | D7: 14.5 | E7: 18.2
A8: 40–44 years | B8: 13.3 | C8: 14.1 | D8: 13.6 | E8: 25.8
A9: 45–49 years | B9: 11.3 | C9: 11.4 | D9: 10.9 | E9: 25
A16: Category | B16: Women (%) | C16: Formal contract (%) | D16: No formal contract (%) | E16: Public servants (%)
A17: Age group
A18: <30 | B18: 47.9 | C18: 16.2 | D18: 43.2 | E18: 16.2 | F18: 222175 | G18: =F18/SUM(F18:F20) -> 0.16206838
A19: 30-39 | B19: 27.5 | C19: 33 | D19: 31.3 | E19: 33 | F19: 452948 | G19: =F19/SUM(F18:F20) -> 0.33040867
A20: 40-49 | B20: 24.6 | C20: 50.8 | D20: 25.4 | E20: 50.8 | F20: 695749 | G20: =F20/SUM(F18:F20) -> 0.50752295
A21: Educational attainment (years of schooling)
A22: < 8 years | B22: 36.4 | C22: 20.4 | D22: 40.1 | E22: 9 | F22: 122901
A23: 8–11 years | B23: 51 | C23: 56.3 | D23: 50.6 | E23: 33.7 | F23: 461148 | H23: Category | I23: Women (%) | J23: Formal contract (%) | K23: No formal contract (%) | L23: Public servants (%) | N23: Status employment | O23: Formal contract (%) | P23: No formal contract (%) | Q23: Public servants (%)
A24: 12 years or more | B24: 12.6 | C24: 23.3 | D24: 9.3 | E24: 57.4 | F24: 786336 | H24: Current religion | N24: Mean | O24: 799 | P24: 426 | Q24: 1148
A25: Race or color | H25: Afro-Brazilian | I25: 0.3 | J25: 0.4 | K25: 0.2 | L25: 2.6 | N25: Median | O25: 508 | P25: 300 | Q25: 840
A26: White | B26: 40.3 | C26: 46.2 | D26: 37.6 | E26: 51.5 | F26: 700554 | H26: Catholic | I26: 61.6 | J26: 61.3 | K26: 59.4 | L26: 66.5 | N26: SD | O26: 923 | P26: 685 | Q26: 1099
A27: Black | B27: 54.5 | C27: 49 | D27: 56.8 | E27: 44.9 | F27: 610856 | H27: Spiritist | I27: 3.4 | J27: 5.1 | K27: 3.1 | L27: 4.6 | N27: Min | O27: 10 | P27: 4 | Q27: 70
A28: Other | B28: 5.2 | C28: 4.8 | D28: 5.6 | E28: 3.6 | F28: 48702 | H28: Evangelical (Pentecostal) | I28: 11.6 | J28: 10.9 | K28: 12.5 | L28: 6.4 | N28: Max | O28: 16000 | P28: 20000 | Q28: 10000
A29: Marital status | H29: Evangelical (Traditional) | I29: 13.1 | J29: 13.7 | K29: 13.6 | L29: 14
A30: Single | B30: 25.8 | C30: 24.6 | D30: 24 | E30: 23.1 | F30: 316287 | H30: None | I30: 8 | J30: 6.2 | K30: 8.8 | L30: 5.2
A31: Married | B31: 36.8 | C31: 37.4 | D31: 36.2 | E31: 44.1 | F31: 604590 | H31: Other | I31: 2 | J31: 2.5 | K31: 2.3 | L31: 0.7
A32: In a union | B32: 27.3 | C32: 24.4 | D32: 28.6 | E32: 17 | F32: 233161 | H32: Religious attendance
A33: Widowed / Separated / Divorced | B33: 10.2 | C33: 13.6 | D33: 11.1 | E33: 15.8 | F33: 216834 | H33: Never | I33: 15.7 | J33: 14.8 | K33: 15.4 | L33: 12.4
A34: Region | H34: Less than once a month | I34: 21.9 | J34: 21.3 | K34: 21.8 | L34: 18.7
A35: Central-West | B35: 7.3 | C35: 6.1 | D35: 7.5 | E35: 8.8 | F35: 120209 | H35: Up to three times a month | I35: 18.1 | J35: 16.8 | K35: 18.6 | L35: 21.3
A36: Northeast | B36: 26.4 | C36: 15 | D36: 28.6 | E36: 17.4 | F36: 239070 | H36: Once a week | I36: 24.1 | J36: 27.4 | K36: 23.2 | L36: 33.8
A37: North | B37: 7.4 | C37: 3.9 | D37: 8.2 | E37: 8 | F37: 109219 | H37: More than once a week | I37: 20.2 | J37: 19.6 | K37: 21 | L37: 13.8
A38: Southeast | B38: 44.1 | C38: 56.4 | D38: 41.1 | E38: 44.5 | F38: 610527
A39: South | B39: 14.9 | C39: 18.6 | D39: 14.6 | E39: 21.3 | F39: 291847
A40: Place of residence | H40: Employment and income status
A41: Rural | B41: 16.3 | C41: 6.6 | D41: 17.1 | E41: 9.8 | F41: 134099 | H41: With income | I41: 85.5 | J41: 90.6 | K41: 81.7 | L41: 98.5
A42: Urban | B42: 83.7 | C42: 93.4 | D42: 82.9 | E42: 90.2 | F42: 1236773 | H42: Not working / without income | I42: 14.5 | J42: 9.4 | K42: 18.3 | L42: 1.5

Sheet Planilha1
A1: ------------------------------------------------------
A2: idade_categ_10 | I2: ------------------------
A3: ------------------------------------------------------ | I3: N | J3: ponderado | K3: para: | L3: mu
B4: Categoria | C4: Mulheres | D4: Funcionarias_Publicas | E4: Com_Carteira | F4: Sem_Carteira | J4: M619B_FILH_cat
A5: 1 | B5: <30 | C5: 25101952 | D5: 222175 | E5: 5131391 | F5: 9822083 | I5: filhos_vivos_incluindo_gravidez_cat | K5: 0 | L5: 1 | M5: 2 | N5: 3 | O5: 4+
A6: 2 | B6: 30-39 | C6: 14374192 | D6: 452948 | E6: 3721373 | F6: 6139318 | J6: 0 | K6: 1375127 | L6: 3144148 | M6: 9591668 | N6: 2120473 | O6: 506524
A7: 3 | B7: 40-49 | C7: 12885312 | D7: 695749 | E7: 3020581 | F7: 5193953 | J7: 1 | K7: 573128 | L7: 3752986 | M7: 5904608 | N7: 1330200 | O7: 517223
A8: 4 | B8: Total | C8: 52361456 | D8: 1370872 | E8: 11873344 | F8: 21155353 | J8: 2 | K8: 703220 | L8: 1046869 | M8: 8029639 | N8: 1988593 | O8: 1073987
J9: 3 | K9: 550239 | L9: 809097 | M9: 1130345 | N9: 2638127 | O9: 1022050
J10: 4+ | K10: 316985 | L10: 470003 | M10: 1602434 | N10: 293615 | O10: 1261671
A11: ------------------------------------------------------
A12: escolarizacao_cat | I12: ------------------------
A13: ------------------------------------------------------ | I13: N | J13: ponderado | K13: para: | L13: pub
B14: Categoria | C14: Mulheres | D14: Funcionarias_Publicas | E14: Com_Carteira | F14: Sem_Carteira | J14: M619B_FILH_cat
A15: 1 | B15: <8 | C15: 18888637 | D15: 122901 | E15: 2392494 | F15: 8420200 | I15: filhos_vivos_incluindo_gravidez_cat | K15: 0 | L15: 1 | M15: 2 | N15: 3 | O15: 4+
A16: 2 | B16: 46334 | C16: 26469641 | D16: 461148 | E16: 6613582 | F16: 10613589 | J16: 0 | K16: 74019 | L16: 62757 | M16: 202448 | N16: 22487 | O16: 21075
A17: 3 | B17: 12+ | C17: 6550377 | D17: 786336 | E17: 2742555 | F17: 1942142 | J17: 1 | K17: 12301 | L17: 133128 | M17: 141336 | N17: 44601 | O17: 20250
A18: 4 | B18: Total | C18: 51908655 | D18: 1370385 | E18: 11748632 | F18: 20975932 | J18: 2 | K18: 518 | L18: 12449 | M18: 306707 | N18: 58755 | O18: 33003
J19: 3 | K19: 17039 | L19: 4203 | M19: 5966 | N19: 76290 | O19: 22719
J20: 4+ | K20: 222 | L20: 1715 | M20: 22388 | N20: 5009 | O20: 23428
A21: ------------------------------------------------------
A22: etnia_cat | I22: ------------------------
A23: ------------------------------------------------------ | I23: N | J23: ponderado | K23: para: | L23: yes
B24: Categoria | C24: Mulheres | D24: Funcionarias_Publicas | E24: Com_Carteira | F24: Sem_Carteira | J24: M619B_FILH_cat
A25: 1 | B25: Branca | C25: 20873916 | D25: 700554 | E25: 5449257 | F25: 7864086 | I25: filhos_vivos_incluindo_gravidez_cat | K25: 0 | L25: 1 | M25: 2 | N25: 3 | O25: 4+
A26: 2 | B26: Negra | C26: 28270123 | D26: 610856 | E26: 5776437 | F26: 11880916 | J26: 0 | K26: 330176 | L26: 697992 | M26: 2454384 | N26: 482624 | O26: 137573
A27: 3 | B27: Outra | C27: 2715173 | D27: 48702 | E27: 568777 | F27: 1174628 | J27: 1 | K27: 155501 | L27: 1005298 | M27: 1556655 | N27: 289341 | O27: 145343
A28: 4 | B28: Total | C28: 51859212 | D28: 1360112 | E28: 11794470 | F28: 20919630 | J28: 2 | K28: 157972 | L28: 136331 | M28: 1919695 | N28: 433989 | O28: 291452
J29: 3 | K29: 123487 | L29: 172435 | M29: 229335 | N29: 418780 | O29: 134873
J30: 4+ | K30: 63056 | L30: 55125 | M30: 214676 | N30: 35177 | O30: 144065
A31: ------------------------------------------------------
A32: estado_conj_cat | I32: ------------------------
A33: ------------------------------------------------------ | I33: N | J33: ponderado | K33: para: | L33: no
B34: Categoria | C34: Mulheres | D34: Funcionarias_Publicas | E34: Com_Carteira | F34: Sem_Carteira | J34: M619B_FILH_cat
A35: 1 | B35: 1.Solteira | C35: 13486168 | D35: 316287 | E35: 2916027 | F35: 5077975 | I35: filhos_vivos_incluindo_gravidez_cat | K35: 0 | L35: 1 | M35: 2 | N35: 3 | O35: 4+
A36: 2 | B36: 2.Casada | C36: 19226004 | D36: 604590 | E36: 4435268 | F36: 7648697 | J36: 0 | K36: 474119 | L36: 1372910 | M36: 3603510 | N36: 811452 | O36: 208392
A37: 3 | B37: 3.Unida | C37: 14288390 | D37: 233161 | E37: 2893957 | F37: 6047442 | J37: 1 | K37: 225199 | L37: 1419785 | M37: 2121199 | N37: 519138 | O37: 229067
A38: 4 | B38: 4.Viuva-Separada-Divorciada-Desquitada | C38: 5313760 | D38: 216834 | E38: 1606833 | F38: 2355973 | J38: 2 | K38: 303955 | L38: 525474 | M38: 3244567 | N38: 876322 | O38: 386611
A39: 5 | B39: Total | C39: 52314322 | D39: 1370872 | E39: 11852086 | F39: 21130088 | J39: 3 | K39: 230035 | L39: 359543 | M39: 500065 | N39: 1192895 | O39: 483259
J40: 4+ | K40: 140229 | L40: 282702 | M40: 748168 | N40: 127886 | O40: 567120
...

Sheet reasons_children
A1: 633- Which of the following reasons best explain why you had children or became pregnant before the age of 20?
A2: Reason | B2: Response | C2: Women (%) | D2: Formal contract (%) | E2: No formal contract (%) | F2: Public servants (%)
A3: Got pregnant unintentionally | B3: Yes | C3: 64.7 | D3: 71.6 | E3: 62.2 | F3: 23
B4: No | C4: 34.7 | D4: 28.3 | E4: 36.7 | F4: 77 | G4: a grande maioria não foi sem querer
B5: Don’t know | C5: 0.6 | D5: 0.1 | E5: 1.1 | F5: 0
A6: Wanted to leave parents’ house | B6: Yes | C6: 24.3 | D6: 22.8 | E6: 23.7 | F6: 27.8
B7: No | C7: 75.6 | D7: 77.1 | E7: 76.2 | F7: 72.2
B8: Don’t know | C8: 0.1 | D8: 0.1 | E8: 0.1 | F8: 0
A9: Wanted to get married | B9: Yes | C9: 38.1 | D9: 27.3 | E9: 40.1 | F9: 46.5 | G9: amais que a media queria casar
B10: No | C10: 61.8 | D10: 72.6 | E10: 59.9 | F10: 53.5
B11: Don’t know | C11: 0.1 | D11: 0.1 | E11: 0.1 | F11: 0
A12: Didn’t know how to avoid having children | B12: Yes | C12: 23.6 | D12: 30.8 | E12: 21.4 | F12: 3.8 | G12: a esmagadora maioria sabeia como evitar filhos, mto mais do que a media
B13: No | C13: 76.3 | D13: 69.1 | E13: 78.5 | F13: 96.2
B14: Don’t know | C14: 0.2 | D14: 0.1 | E14: 0.1 | F14: 0
A15: Didn’t have money to buy contraceptives | B15: Yes | C15: 18.5 | D15: 16.8 | E15: 17.6 | F15: 1.2
B16: No | C16: 81.2 | D16: 83.1 | E16: 82.3 | F16: 98.8 | G16: a grande maioria tinha dinheiro pra comprar contraceptivo
B17: Don’t know | C17: 0.4 | D17: 0.1 | E17: 0.1 | F17: 0
A18: Married early | B18: Yes | C18: 51.1 | D18: 47.4 | E18: 50.1 | F18: 93.4
B19: No | C19: 48.9 | D19: 52.5 | E19: 49.8 | F19: 6.6 | G19: a grande maioria casou cedo
B20: Don’t know | C20: 0.1 | D20: 0.1 | E20: 0 | F20: 0
A21: Had no other option | B21: Yes | C21: 16.3 | D21: 28.2 | E21: 14.9 | F21: 13.2
B22: No | C22: 83.2 | D22: 71.7 | E22: 84.7 | F22: 86.8
B23: Don’t know | C23: 0.5 | D23: 0.2 | E23: 0.4 | F23: 0
A24: Wanted to be a mother right away | B24: Yes | C24: 38.4 | D24: 26.9 | E24: 40.1 | F24: 49.1 | G24: metade delas quis se tornar mae
B25: No | C25: 60.9 | D25: 71.7 | E25: 59.6 | F25: 23
B26: Don’t know | C26: 0.7 | D26: 1.4 | E26: 0.2 | F26: 27.8
A27: Husband/partner wanted to have children right away | B27: Yes | C27: 42.1 | D27: 28.3 | E27: 41.7 | F27: 91.8 | G27: marido queria agora
B28: No | C28: 55.9 | D28: 70.8 | E28: 55.8 | F28: 8.2
B29: Don’t know | C29: 2 | D29: 0.8 | E29: 2.5 | F29: 0
A30: Did not know where to get contraception | B30: Yes | C30: 16.3 | D30: 13.3 | E30: 13.5 | F30: 0
B31: No | C31: 83.6 | D31: 86.6 | E31: 86.3 | F31: 100 | G31: todas com acesso a informaçao e ao metodo
B32: Don’t know | C32: 0.1 | D32: 0.1 | E32: 0.1 | F32: 0
A33: Method failed (forgot pill, condom failure, etc.) | B33: Yes | C33: 20.2 | D33: 18.8 | E33: 23.6 | F33: 8.7
B34: No | C34: 79.5 | D34: 79.3 | E34: 76.3 | F34: 91.3 | G34: a maioria o metodo não falhou, o que corrobora com querer acima
B35: Don’t know | C35: 0.3 | D35: 1.9 | E35: 0.1 | F35: 0
A36: Other reasons | B36: Yes | C36: 0.9 | D36: 1.4 | E36: 1.4 | F36: 0
B37: No | C37: 99.1 | D37: 98.6 | E37: 98.6 | F37: 100
A39: 637 Which of the following reasons best explains why you did not have any live births before the age of 30?
A40: Reason | B40: Response | C40: Women (%) | D40: Formal contract (%) | E40: No formal contract (%) | F40: Public servants (%)
A41: Never wanted to have children | B41: Yes | C41: 26.4 | D41: 25.8 | E41: 27.3 | F41: 31.1
...

Sheet achived x desired
A2: ------------------------
A3: Resultados | B3: para: | C3: mu
B4: All Women | C4: Desired number of children
A5: M619B_FILH_cat | B5: Number of achived children | C5: 0 | D5: 1 | E5: 2 | F5: 3 | G5: 4+
B6: 0 | C6: 0.08215631 | D6: 0.18784558 | E6: 0.57304948 | F6: 0.12668662 | G6: 0.03026201
B7: 1 | C7: 0.04745164 | D7: 0.31072538 | E7: 0.48886714 | F7: 0.11013276 | G7: 0.04282307
B8: 2 | C8: 0.05475808 | D8: 0.08151718 | E8: 0.62524894 | F8: 0.15484701 | G8: 0.0836288
B9: 3 | C9: 0.08947183 | D9: 0.13156356 | E9: 0.18380021 | F9: 0.42897359 | G9: 0.16619081
B10: 4+ | C10: 0.08035692 | D10: 0.11914772 | E10: 0.40622374 | F10: 0.07443269 | G10: 0.31983892
A12: ------------------------
A13: Resultados | B13: para: | C13: pub
B14: pub | C14: Desired number of children
A15: M619B_FILH_cat | B15: Number of achived children | C15: 0 | D15: 1 | E15: 2 | F15: 3 | G15: 4+
B16: 0 | C16: 0.19336953 | D16: 0.16394734 | E16: 0.5288798 | F16: 0.058745409 | G16: 0.055057922
B17: 1 | C17: 0.034984754 | D17: 0.3786172 | E17: 0.40196074 | F17: 0.12684536 | G17: 0.057591945
B18: 2 | C18: 0.001260061 | D18: 0.030257289 | E18: 0.74546153 | F18: 0.14280524 | G18: 0.080215871
B19: 3 | C19: 0.13499422 | D19: 0.033303409 | E19: 0.047265467 | F19: 0.60443562 | G19: 0.18000129
B20: 4+ | C20: 0.004205733 | D20: 0.032497804 | E20: 0.42432319 | F20: 0.094937201 | G20: 0.44403607
A22: ------------------------
A23: Resultados | B23: para: | C23: yes
B24: yes | C24: Desired number of children
A25: M619B_FILH_cat | B25: Number of achived children | C25: 0 | D25: 1 | E25: 2 | F25: 3 | G25: 4+
B26: 0 | C26: 0.08047684 | D26: 0.1701278 | E26: 0.59822902 | F26: 0.11763435 | G26: 0.03353198
B27: 1 | C27: 0.04933176 | D27: 0.31892582 | E27: 0.49384091 | F27: 0.09179211 | G27: 0.0461094
B28: 2 | C28: 0.0537424 | D28: 0.04637994 | E28: 0.65308217 | F28: 0.14764336 | G28: 0.09915214
B29: 3 | C29: 0.11445575 | D29: 0.159823 | E29: 0.21256191 | F29: 0.38815113 | G29: 0.12500821
B30: 4+ | C30: 0.12313242 | D30: 0.10764492 | E30: 0.41920887 | F30: 0.06869114 | G30: 0.28132265
A32: ------------------------
A33: Resultados | B33: para: | C33: no
B34: no | C34: Desired number of children
A35: M619B_FILH_cat | B35: Number of achived children | C35: 0 | D35: 1 | E35: 2 | F35: 3 | G35: 4+
B36: 0 | C36: 0.07327524 | D36: 0.21218381 | E36: 0.5569237 | F36: 0.12541022 | G36: 0.03220704
B37: 1 | C37: 0.04988474 | D37: 0.31450221 | E37: 0.4698753 | F37: 0.11499628 | G37: 0.05074147
B38: 2 | C38: 0.05695319 | D38: 0.09845994 | E38: 0.60794644 | F38: 0.16419961 | G38: 0.07244081
B39: 3 | C39: 0.08317132 | D39: 0.12999607 | E39: 0.18080321 | F39: 0.43130252 | G39: 0.17472688
B40: 4+ | C40: 0.07514513 | D40: 0.1514931 | E40: 0.40092492 | F40: 0.0685311 | G40: 0.30390575
A47: ------------------------
A48: Resultados | B48: para: | C48: mu
B49: M619B_FILH_cat
A50: filhos_vivos_incluindo_gravidez_cat | B50: 0 | C50: 1 | D50: 2 | E50: 3 | F50: 4+
...

Sheet nascidos
A1: > | B1: #total
A2: > | B2: svytable(~M236_TOTA+idade_categ | C2: design | D2: = | E2: mu)
B3: idade_categ
A4: M236_TOTA | C4: <20 | D4: 20-24 | E4: 25-29 | F4: 30-34 | G4: 35-39 | H4: 40-44 | I4: 45-49 | J4: total
B5: 0 | C5: 7058627.8 | D5: 4454962 | E5: 2591187.9 | F5: 1231445.8 | G5: 962857.93 | H5: 666197.69 | I5: 798177.88 | J5: =SUM(C5:I5) -> 17763457
B6: 1 | C6: 1175591.6 | D6: 2558709.8 | E6: 2414794 | F6: 1808178.5 | G6: 1603725.7 | H6: 1276629.4 | I6: 847451.48 | J6: =SUM(C6:I6) -> 11685080
B7: 2 | C7: 163484.35 | D7: 1178151.5 | E7: 1710284.5 | F7: 2385446 | G7: 2371004.3 | H7: 2412963.1 | I7: 1710077 | J7: =SUM(C7:I7) -> 11931411
B8: 3 | C8: 19000.129 | D8: 387222.5 | E8: 977716.69 | F8: 1249019.1 | G8: 1211616.8 | H8: 1420700.5 | I8: 1142485.7 | J8: =SUM(C8:I8) -> 6407761.5
B9: 4 | C9: 1092.2003 | D9: 63221.399 | E9: 245030.37 | F9: 313283.53 | G9: 561620.6 | H9: 505777.65 | I9: 618045.53 | J9: =SUM(C9:I9) -> 2308071.3
B10: 5 | C10: 0 | D10: 11404.832 | E10: 66963.979 | F10: 178930.15 | G10: 178661.56 | H10: 313574.61 | I10: 279621.56 | J10: =SUM(C10:I10) -> 1029156.7
B11: 6 | C11: 0 | D11: 2627.6026 | E11: 13137.186 | F11: 69458.22 | G11: 75017.564 | H11: 163144.78 | I11: 255457.98 | J11: =SUM(C11:I11) -> 578843.33
B12: 7 | C12: 0 | D12: 4354.6496 | E12: 1510.9247 | F12: 35080.942 | G12: 84800.699 | H12: 69580.24 | I12: 86491.805 | J12: =SUM(C12:I12) -> 281819.26
B13: 8 | C13: 0 | D13: 0 | E13: 2876.3081 | F13: 4300.8181 | G13: 17688.138 | H13: 30369.085 | I13: 85326.235 | J13: =SUM(C13:I13) -> 140560.58
B14: 9 | C14: 0 | D14: 0 | E14: 0 | F14: 652.7242 | G14: 24173.34 | H14: 46940.233 | I14: 27106.973 | J14: =SUM(C14:I14) -> 98873.27
B15: 10 | C15: 0 | D15: 0 | E15: 0 | F15: 567.9368 | G15: 2039.4108 | H15: 7364.3735 | I15: 52032.424 | J15: =SUM(C15:I15) -> 62004.145
B16: 11 | C16: 0 | D16: 0 | E16: 0 | F16: 0 | G16: 2153.5619 | H16: 28691.307 | I16: 10519.45 | J16: =SUM(C16:I16) -> 41364.319
... B21: 16 | C21: 0 | D21: 0 | E21: 0 | F21: 0 | G21: 0 | H21: 0 | I21: 7263.7302 | J21: =SUM(C21:I21) -> 7263.7302
A22: > | C22: =SUMPRODUCT($B$5:$B$21,C5:C21) -> 1563929.5 | D22: =SUMPRODUCT($B$5:$B$21,D5:D21) -> 6432838.1 | E22: =SUMPRODUCT($B$5:$B$21,E5:E21) -> 10195865 | F22: =SUMPRODUCT($B$5:$B$21,F5:F21) -> 13182189 | G22: =SUMPRODUCT($B$5:$B$21,G5:G21) -> 14598846 | H22: =SUMPRODUCT($B$5:$B$21,H5:H21) -> 16549205 | I22: =SUMPRODUCT($B$5:$B$21,I5:I21) -> 15600225 | J22: =SUM(C22:I22) -> 78123097
C23: =C22/SUM(C5:C21) -> 0.18578847 | D23: =D22/SUM(D5:D21) -> 0.74276584 | E23: =E22/SUM(E5:E21) -> 1.2707499 | F23: =F22/SUM(F5:F21) -> 1.8116451 | G23: =G22/SUM(G5:G21) -> 2.0568047 | H23: =H22/SUM(H5:H21) -> 2.3819344 | I23: =I22/SUM(I5:I21) -> 2.6274012 | J23: =J22/SUM(J5:J21) -> 1.4919963
A26: > | B26: # | C26: Situacaoo | D26: domicilio
A27: > | B27: svytable(~M236_TOTA+idade_categ+CM008_SITU | C27: design | D27: = | E27: mu)
B28: CM008_SITU | C28: = | D28: 1
B30: idade_categ
A31: M236_TOTA | C31: <20 | D31: 20-24 | E31: 25-29 | F31: 30-34 | G31: 35-39 | H31: 40-44 | I31: 45-49 | J31: total
B32: 0 | C32: 5850338 | D32: 3846243 | E32: 2326078 | F32: 1082566 | G32: 902476.8 | H32: 578971.8 | I32: 690093.3 | J32: =SUM(C32:I32) -> 15276767
B33: 1 | C33: 902780.6 | D33: 2010803 | E33: 2087317 | F33: 1630837 | G33: 1407120 | H33: 1162413 | I33: 797404.6 | J33: =SUM(C33:I33) -> 9998675.2
B34: 2 | C34: 123242.6 | D34: 967486.4 | E34: 1292793 | F34: 1974331 | G34: 2031901 | H34: 2017592 | I34: 1528128 | J34: =SUM(C34:I34) -> 9935474
B35: 3 | C35: 4120.185 | D35: 270401.7 | E35: 802988.4 | F35: 1022087 | G35: 994626.4 | H35: 1214943 | I35: 958804.1 | J35: =SUM(C35:I35) -> 5267970.8
B36: 4 | C36: 0 | D36: 42367.58 | E36: 174777.8 | F36: 232232.9 | G36: 430270.7 | H36: 377087.7 | I36: 516256 | J36: =SUM(C36:I36) -> 1772992.7
B37: 5 | C37: 0 | D37: 4699.373 | E37: 55059.24 | F37: 125743.8 | G37: 130888.9 | H37: 212848.9 | I37: 214023.4 | J37: =SUM(C37:I37) -> 743263.61
B38: 6 | C38: 0 | D38: 1099.206 | E38: 9655.541 | F38: 50546.79 | G38: 37126.3 | H38: 115177.3 | I38: 201143.4 | J38: =SUM(C38:I38) -> 414748.54
B39: 7 | C39: 0 | D39: 4354.65 | E39: 317.6095 | F39: 31537.48 | G39: 62615.53 | H39: 36897.42 | I39: 32459.33 | J39: =SUM(C39:I39) -> 168182.02
B40: 8 | C40: 0 | D40: 0 | E40: 0 | F40: 2318.267 | G40: 9981.272 | H40: 18595.95 | I40: 62930.48 | J40: =SUM(C40:I40) -> 93825.969
B41: 9 | C41: 0 | D41: 0 | E41: 0 | F41: 652.7242 | G41: 20242.72 | H41: 28877.64 | I41: 21996.2 | J41: =SUM(C41:I41) -> 71769.284
B42: 10 | C42: 0 | D42: 0 | E42: 0 | F42: 68.60361 | G42: 189.0732 | H42: 5048.368 | I42: 34140.79 | J42: =SUM(C42:I42) -> 39446.835
B43: 11 | C43: 0 | D43: 0 | E43: 0 | F43: 0 | G43: 1990.55 | H43: 14108.75 | I43: 4347.684 | J43: =SUM(C43:I43) -> 20446.984
... B48: 16 | C48: 0 | D48: 0 | E48: 0 | F48: 0 | G48: 0 | H48: 0 | I48: 7263.73 | J48: =SUM(C48:I48) -> 7263.73
C49: =SUMPRODUCT($B$32:$B$48,C32:C48) -> 1161626.4 | D49: =SUMPRODUCT($B$32:$B$48,D32:D48) -> 4987025.9 | E49: =SUMPRODUCT($B$32:$B$48,E32:E48) -> 8116432.1 | F49: =SUMPRODUCT($B$32:$B$48,F32:F48) -> 10752560 | G49: =SUMPRODUCT($B$32:$B$48,G32:G48) -> 11800282 | H49: =SUMPRODUCT($B$32:$B$48,H32:H48) -> 13023825 | I49: =SUMPRODUCT($B$32:$B$48,I32:I48) -> 12665805 | J49: =SUM(C49:I49) -> 62507556
B51: CM008_SITU | C51: = | D51: 2
B53: idade_categ
...

Sheet desejados
A1: > | B1: #total
A2: > | B2: svytable(~M236_TOTA+idade_categ | C2: design | D2: = | E2: mu)
B3: idade_categ
A4: M236_TOTA | C4: <20 | D4: 20-24 | E4: 25-29 | F4: 30-34 | G4: 35-39 | H4: 40-44 | I4: 45-49 | J4: total
B5: 0 | C5: 697839.7 | D5: 526746 | E5: 445470.1 | F5: 497812.9 | G5: 493104.4 | H5: 396245.7 | I5: 461480.3 | J5: =SUM(C5:I5) -> 3518699.1
B6: 1 | C6: 1511189 | D6: 2024128 | E6: 1708728 | F6: 1280256 | G6: 1017685 | H6: 885856.6 | I6: 795260.6 | J6: =SUM(C6:I6) -> 9223103.2
B7: 2 | C7: 4741306 | D7: 4552356 | E7: 4269818 | F7: 3649949 | G7: 3462222 | H7: 3126314 | I7: 2456730 | J7: =SUM(C7:I7) -> 26258695
B8: 3 | C8: 1094546 | D8: 1157093 | E8: 1197828 | F8: 1262847 | G8: 1313202 | H8: 1325872 | I8: 1019620 | J8: =SUM(C8:I8) -> 8371008
